Workbook

Sheet 商检明细
A1: 商检单
A2: 基本信息
A3: 发票号 | B3: {invoiceCode} | C3: 单据编号 | D3: {code} | E3: 录入日期 | F3: {inputDate} | G3: 录入人 | H3: {inputUserName}
A4: 状态 | B4: {status} | C4: 审核日期 | E4: 审核人 | G4: 出运日期 | H4: {shipDate}
A5: 外销合同 | B5: {saleContractCode} | C5: 客户合同 | D5: {custPo} | E5: 客户编号 | F5: {custCode} | G5: 客户名称 | H5: {custName}
A6: 外销币种 | B6: {currency} | C6: 贸易国别 | D6: {tradeCountryName} | E6: 贸易方式 | F6: {tradeType} | G6: 价格条款 | H6: {settlementTermType}
A7: 结汇方式 | B7: {settlementName} | C7: 结汇方式 | E7: 船代公司 | F7: {forwarderCompanyName} | G7: 集装箱数量 | H7: {containerQuantity}
A8: 运输方式 | B8: {transportType} | C8: 出运口岸 | D8: {departurePortName} | E8: 目的口岸 | F8: {destinationPortName} | G8: 出运单号 | H8: {shipmentCode}
A9: 合计
A10: 数量合计 | B10: {totalQuantity} | C10: 箱数合计 | D10: {totalBoxes} | E10: 毛重合计 | F10: {totalGrossweight} | G10: 净重合计 | H10: {totalWeight}
A11: 体积合计 | B11: {totalVolume}
A12: 备注信息
A13: 抬头人 | B13: {companyTitle} | C13: 备注 | D13: {remark} | E13: 收货人 | F13: {receivePerson} | G13: 通知人 | H13: {notifyPerson}
A14: 正面唛头 | B14: {frontShippingMark}
A16: 序号 | B16: 中文品名 | C16: 英文品名 | D16: 申报要素 | E16: 数量 | F16: 销售单价 | G16: 金额 | H16: 报关单位 | I16: 采购币种 | J16: 采购单价 | K16: 采购总价 | L16: HS编码 | M16: 退税率% | N16: 退税金额 | O16: 采购员编号 | P16: 采购员名称 | Q16: 厂商简称 | R16: 箱数 | S16: 外箱单位 | T16: 外箱体积 | U16: 总体积 | V16: 外箱毛重 | W16: 总毛重 | X16: 外箱净重 | Y16: 总净重
A17: {.sortNum} | B17: {.declarationName} | C17: {.customsDeclarationNameEng} | D17: {.customsDeclareElements} | E17: {.declarationQuantity} | F17: {.saleUnitPriceAmount} | G17: {.saleAmountAmount} | H17: {.hsMeasureUnitName} | I17: {.purchaseCurrency} | J17: {.purchaseUnitPriceAmount} | K17: {.purchaseTotalAmountAmount} | L17: {.hsCode} | M17: {.taxRefundRate} | N17: {.taxRefundPriceAmount} | O17: {.purchaseUserCode} | P17: {.purchaseUserName} | Q17: {.venderName} | R17: {.boxCount} | S17: {.unitPerOuterbox} | T17: {.outerboxVolume} | U17: {.totalVolume} | V17: {.outerboxGrossweightWeight} | W17: {.totalGrossweightWeight} | X17: {.outerboxNetweightWeight} | Y17: {.totalNetweightWeight}

Sheet 报关发票
A1: =商检明细!B13 -> {companyTitle}
A2: =VLOOKUP(A1,资料!A3:D8,2,0) -> #N/A
A3: =VLOOKUP(A1,资料!A3:D8,3,0) -> #N/A
A5: COMMERCIAL INVOICE
A7: 付款方式 | E7: 发票号码 | H7: =商检明细!B3 -> {invoiceCode}
A8: PAYMENT | E8: INV.NO.
A10: 合同号码 | B10: =商检明细!B5 -> {saleContractCode} | E10: 日 期 | H10: =LEFT(商检明细!F3,10) -> {inputDate
A11: CONTRACT NO. | E11: DATE:
A13: 客 户 | B13: =商检明细!H5 -> {custName}
A14: MESSRS
A16: 地 址
A17: ADDRESS
A19: 船 由 | B19: =商检明细!B8 -> {transportType}
A20: FROM
B22: 货 名 | C22: 件 数 | E22: 数 量 | G22: 单 价 | I22: 金 额
B23: DESCRIPTION | C23: PKG | E23: QTY | G23: UNIT PRICE | I23: AMOUNT
G24: =商检明细!H6&" "&商检明细!D8 -> {settlementTermType} {departurePortName}
B25: =商检明细!C17 -> {.customsDeclarationNameEng} | C25: =商检明细!R17 -> {.boxCount} | D25: =商检明细!S17 -> {.unitPerOuterbox} | E25: =商检明细!E17 -> {.declarationQuantity} | F25: =IF(E25=0,"","PCS") -> PCS | G25: =商检明细!B6 -> {currency} | H25: =商检明细!F17 -> {.saleUnitPriceAmount} | I25: =商检明细!G17 -> {.saleAmountAmount}
B26: =商检明细!C18 -> 0 | C26: =商检明细!R18 -> 0 | D26: =商检明细!S18 -> 0 | E26: =商检明细!E18 -> 0 | F26: =IF(E26=0,"","PCS") | H26: =商检明细!F18 -> 0 | I26: =商检明细!G18 -> 0
B27: =商检明细!C19 -> 0 | C27: =商检明细!R19 -> 0 | D27: =商检明细!S19 -> 0 | E27: =商检明细!E19 -> 0 | F27: =IF(E27=0,"","PCS") | H27: =商检明细!F19 -> 0 | I27: =商检明细!G19 -> 0
B28: =商检明细!C20 -> 0 | C28: =商检明细!R20 -> 0 | D28: =商检明细!S20 -> 0 | E28: =商检明细!E20 -> 0 | F28: =IF(E28=0,"","PCS") | H28: =商检明细!F20 -> 0 | I28: =商检明细!G20 -> 0
B29: =商检明细!C21 -> 0 | C29: =商检明细!R21 -> 0 | D29: =商检明细!S21 -> 0 | E29: =商检明细!E21 -> 0 | F29: =IF(E29=0,"","PCS") | H29: =商检明细!F21 -> 0 | I29: =商检明细!G21 -> 0
B30: =商检明细!C22 -> 0 | C30: =商检明细!R22 -> 0 | D30: =商检明细!S22 -> 0 | E30: =商检明细!E22 -> 0 | F30: =IF(E30=0,"","PCS") | H30: =商检明细!F22 -> 0 | I30: =商检明细!G22 -> 0
B31: =商检明细!C23 -> 0 | C31: =商检明细!R23 -> 0 | D31: =商检明细!S23 -> 0 | E31: =商检明细!E23 -> 0 | F31: =IF(E31=0,"","PCS") | H31: =商检明细!F23 -> 0 | I31: =商检明细!G23 -> 0
B32: =商检明细!C24 -> 0 | C32: =商检明细!R24 -> 0 | D32: =商检明细!S24 -> 0 | E32: =商检明细!E24 -> 0 | F32: =IF(E32=0,"","PCS") | H32: =商检明细!F24 -> 0 | I32: =商检明细!G24 -> 0
B33: =商检明细!C25 -> 0 | C33: =商检明细!R25 -> 0 | D33: =商检明细!S25 -> 0 | E33: =商检明细!E25 -> 0 | F33: =IF(E33=0,"","PCS") | H33: =商检明细!F25 -> 0 | I33: =商检明细!G25 -> 0
B34: =商检明细!C26 -> 0 | C34: =商检明细!R26 -> 0 | D34: =商检明细!S26 -> 0 | E34: =商检明细!E26 -> 0 | F34: =IF(E34=0,"","PCS") | H34: =商检明细!F26 -> 0 | I34: =商检明细!G26 -> 0
B35: =商检明细!C27 -> 0 | C35: =商检明细!R27 -> 0 | D35: =商检明细!S27 -> 0 | E35: =商检明细!E27 -> 0 | F35: =IF(E35=0,"","PCS") | H35: =商检明细!F27 -> 0 | I35: =商检明细!G27 -> 0
B36: TOTAL: | C36: =SUM(C25:C35) -> 0 | D36: =D25 -> {.unitPerOuterbox} | E36: =SUM(E25:E35) -> 0 | F36: =F25 -> PCS | I36: =SUM(I25:I35) -> 0
A37: =商检明细!B14 -> {frontShippingMark}

Sheet 报关箱单
A1: =商检明细!B13 -> {companyTitle}
A2: =VLOOKUP(A1,资料!A3:D8,2,0) -> #N/A
A3: =VLOOKUP(A1,资料!A3:D8,3,0) -> #N/A
A5: PACKING LIST
A6: 付款方式 | F6: 发票号码 | H6: =商检明细!B3 -> {invoiceCode}
A7: PAYMENT | F7: INV.NO.
A8: 合同号码 | B8: =商检明细!B5 -> {saleContractCode} | F8: 日 期 | H8: =LEFT(商检明细!F3,10) -> {inputDate
A9: CONTRACT NO. | F9: DATE:
A10: 客 户 | B10: =商检明细!H5 -> {custName}
A11: MESSRS
A12: 地 址
A13: ADDRESS
A14: 船 由 | B14: BY SEA
A15: FROM
B16: 货 名 | C16: 件 数 | E16: 数 量 | G16: 毛 重 | H16: 净 重 | I16: 体 积
B17: DESCRIPTION | C17: PKG | E17: QTY | G17: G.W. | H17: N.W. | I17: MEAS.
G18: KGS | H18: KGS | I18: CBM
B20: =商检明细!C17 -> {.customsDeclarationNameEng} | C20: =商检明细!R17 -> {.boxCount} | D20: =商检明细!S17 -> {.unitPerOuterbox} | E20: =商检明细!E17 -> {.declarationQuantity} | F20: =IF(E20=0,"","PCS") -> PCS | G20: =商检明细!W17 -> {.totalGrossweightWeight} | H20: =商检明细!Y17 -> {.totalNetweightWeight} | I20: =商检明细!U17 -> {.totalVolume}
B21: =商检明细!C18 -> 0 | C21: =商检明细!R18 -> 0 | D21: =商检明细!S18 -> 0 | E21: =商检明细!E18 -> 0 | F21: =IF(E21=0,"","PCS") | G21: =商检明细!W18 -> 0 | H21: =商检明细!Y18 -> 0 | I21: =商检明细!U18 -> 0
B22: =商检明细!C19 -> 0 | C22: =商检明细!R19 -> 0 | D22: =商检明细!S19 -> 0 | E22: =商检明细!E19 -> 0 | F22: =IF(E22=0,"","PCS") | G22: =商检明细!W19 -> 0 | H22: =商检明细!Y19 -> 0 | I22: =商检明细!U19 -> 0
B23: =商检明细!C20 -> 0 | C23: =商检明细!R20 -> 0 | D23: =商检明细!S20 -> 0 | E23: =商检明细!E20 -> 0 | F23: =IF(E23=0,"","PCS") | G23: =商检明细!W20 -> 0 | H23: =商检明细!Y20 -> 0 | I23: =商检明细!U20 -> 0
B24: =商检明细!C21 -> 0 | C24: =商检明细!R21 -> 0 | D24: =商检明细!S21 -> 0 | E24: =商检明细!E21 -> 0 | F24: =IF(E24=0,"","PCS") | G24: =商检明细!W21 -> 0 | H24: =商检明细!Y21 -> 0 | I24: =商检明细!U21 -> 0
B25: =商检明细!C22 -> 0 | C25: =商检明细!R22 -> 0 | D25: =商检明细!S22 -> 0 | E25: =商检明细!E22 -> 0 | F25: =IF(E25=0,"","PCS") | G25: =商检明细!W22 -> 0 | H25: =商检明细!Y22 -> 0 | I25: =商检明细!U22 -> 0
B26: =商检明细!C23 -> 0 | C26: =商检明细!R23 -> 0 | D26: =商检明细!S23 -> 0 | E26: =商检明细!E23 -> 0 | F26: =IF(E26=0,"","PCS") | G26: =商检明细!W23 -> 0 | H26: =商检明细!Y23 -> 0 | I26: =商检明细!U23 -> 0
B27: =商检明细!C24 -> 0 | C27: =商检明细!R24 -> 0 | D27: =商检明细!S24 -> 0 | E27: =商检明细!E24 -> 0 | F27: =IF(E27=0,"","PCS") | G27: =商检明细!W24 -> 0 | H27: =商检明细!Y24 -> 0 | I27: =商检明细!U24 -> 0
B28: =商检明细!C25 -> 0 | C28: =商检明细!R25 -> 0 | D28: =商检明细!S25 -> 0 | E28: =商检明细!E25 -> 0 | F28: =IF(E28=0,"","PCS") | G28: =商检明细!W25 -> 0 | H28: =商检明细!Y25 -> 0 | I28: =商检明细!U25 -> 0
B29: =商检明细!C26 -> 0 | C29: =商检明细!R26 -> 0 | D29: =商检明细!S26 -> 0 | E29: =商检明细!E26 -> 0 | F29: =IF(E29=0,"","PCS") | G29: =商检明细!W26 -> 0 | H29: =商检明细!Y26 -> 0 | I29: =商检明细!U26 -> 0
B30: =商检明细!C27 -> 0 | C30: =商检明细!R27 -> 0 | D30: =商检明细!S27 -> 0 | E30: =商检明细!E27 -> 0 | F30: =IF(E30=0,"","PCS") | G30: =商检明细!W27 -> 0 | H30: =商检明细!Y27 -> 0 | I30: =商检明细!U27 -> 0
B31: TOTAL: | C31: =SUM(C20:C30) -> 0 | D31: =D20 -> {.unitPerOuterbox} | E31: =SUM(E20:E30) -> 0 | F31: =F20 -> PCS | G31: =SUM(G20:G30) -> 0 | H31: =SUM(H20:H30) -> 0 | I31: =SUM(I20:I30) -> 0
A34: =商检明细!B14 -> {frontShippingMark}

Sheet 报关单
A1: 中华人民共和国海关出口货物报关单（最新版）
A2: 预录入编号: | D2: 海关编号: | I2: 页码/页数：
A3: 境内发货人 | G3: 出境关别 | I3: 出口日期 | K3: 申报日期 | L3: 备案号
A4: =VLOOKUP(D4,资料!A3:G8,7,0) -> #N/A | C4: =VLOOKUP(D4,资料!A3:G8,6,0) -> #N/A | D4: =商检明细!B13 -> {companyTitle} | G4: 宁波海关 | I4: =LEFT(商检明细!H4,10) -> {shipDate}
A5: 境外收货人 | G5: 运输方式 | I5: 运输工具名称及航次号 | K5: 提运单号
A6: =商检明细!H5 -> {custName} | G6: =商检明细!B8 -> {transportType}
A7: 生产销售单位 | G7: 监管方式 | I7: 征免性质 | K7: 许可证号
A8: =VLOOKUP(D8,资料!A3:G8,7,0) -> #N/A | C8: =VLOOKUP(D8,资料!A3:G8,6,0) -> #N/A | D8: =商检明细!B13 -> {companyTitle} | G8: 一般贸易 | I8: 一般征税
A9: 合同协议号 | D9: 贸易国（地区） | G9: 运抵国（地区） | K9: 指运港 | L9: 离境口岸
A10: =商检明细!B5 -> {saleContractCode} | D10: =商检明细!D6 -> {tradeCountryName} | G10: =商检明细!D6 -> {tradeCountryName} | K10: =商检明细!F8 -> {destinationPortName} | L10: =商检明细!D8 -> {departurePortName}
A11: 运输包装种类 | C11: 件数 | D11: 其他包装种类及对应数量 | E11: 毛重（千克） | G11: 净重（千克） | H11: 成交方式 | I11: 运费（金额、币制） | K11: 保费（金额、币制） | M11: 杂费（金额、币制）
A12: 纸箱 | C12: =商检明细!D10&"CTNS" -> {totalBoxes}CTNS | E12: =商检明细!F10 -> {totalGrossweight} | G12: =商检明细!H10 -> {totalWeight} | H12: FOB
A13: 随附单证及编号
A15: 标记唛码及备注
A17: 项号 | B17: 商品编号 | C17: 商品名称 | E17: 数量 | F17: 单位 | G17: 单价 | H17: 总价 | I17: 币制 | J17: 原产国（地区） | K17: 最终目的国（地区） | L17: 境内货源地 | M17: 征免
A18: 1 | B18: =商检明细!L17 -> {.hsCode} | C18: =INDEX(商检明细!$A$17:$V$100,A18,3) -> {.customsDeclarationNameEng} | E18: =INDEX(商检明细!$A$17:$Y$64,A18,5) -> {.declarationQuantity} | F18: =INDEX(商检明细!$A$17:$Y$64,A18,8) -> {.hsMeasureUnitName} | G18: =INDEX(商检明细!$A$17:$Y$64,A18,6) -> {.saleUnitPriceAmount} | H18: =INDEX(商检明细!$A$17:$Y$64,A18,7) -> {.saleAmountAmount} | I18: =IF(H18=0,"","美元") -> 美元 | J18: =IF(H18=0,"","中国") -> 中国 | K18: =商检明细!D6 -> {tradeCountryName} | L18: =IF(H18=0,"","宁波") -> 宁波 | M18: =IF(H18=0,"","照章征税") -> 照章征税
C19: =INDEX(商检明细!$A$17:$V$100,A18,2) -> {.declarationName} | E19: =INDEX(商检明细!$A$17:$Y$64,A18,25) -> {.totalNetweightWeight} | F19: =IF(E19=0,"","千克") -> 千克
C20: =INDEX(商检明细!$A$17:$V$100,A18,4) -> {.customsDeclareElements}
A21: 2 | C21: =INDEX(商检明细!$A$17:$V$100,A21,3) -> 0 | E21: =INDEX(商检明细!$A$17:$Y$64,A21,5) -> 0 | F21: =INDEX(商检明细!$A$17:$Y$64,A21,8) -> 0 | G21: =INDEX(商检明细!$A$17:$Y$64,A21,6) -> 0 | H21: =INDEX(商检明细!$A$17:$Y$64,A21,7) -> 0 | I21: =IF(H21=0,"","美元") | J21: =IF(H21=0,"","中国") | K21: =G$10 -> {tradeCountryName} | L21: =IF(H21=0,"","宁波") | M21: =IF(H21=0,"","照章征税")
C22: =INDEX(商检明细!$A$17:$V$100,A21,2) -> 0 | E22: =INDEX(商检明细!$A$17:$Y$64,A21,25) -> 0 | F22: =IF(E22=0,"","千克")
C23: =INDEX(商检明细!$A$17:$V$100,A21,4) -> 0
A24: 3 | C24: =INDEX(商检明细!$A$17:$V$100,A24,3) -> 0 | E24: =INDEX(商检明细!$A$17:$Y$64,A24,5) -> 0 | F24: =INDEX(商检明细!$A$17:$Y$64,A24,8) -> 0 | G24: =INDEX(商检明细!$A$17:$Y$64,A24,6) -> 0 | H24: =INDEX(商检明细!$A$17:$Y$64,A24,7) -> 0 | I24: =IF(H24=0,"","美元") | J24: =IF(H24=0,"","中国") | K24: =G$10 -> {tradeCountryName} | L24: =IF(H24=0,"","宁波") | M24: =IF(H24=0,"","照章征税")
E25: =INDEX(商检明细!$A$17:$Y$64,A24,25) -> 0 | F25: =IF(E25=0,"","千克")
A27: 4 | C27: =INDEX(商检明细!$A$17:$V$100,A27,3) -> 0 | E27: =INDEX(商检明细!$A$17:$Y$64,A27,5) -> 0 | F27: =INDEX(商检明细!$A$17:$Y$64,A27,8) -> 0 | G27: =INDEX(商检明细!$A$17:$Y$64,A27,6) -> 0 | H27: =INDEX(商检明细!$A$17:$Y$64,A27,7) -> 0 | I27: =IF(H27=0,"","美元") | J27: =IF(H27=0,"","中国") | K27: =G$10 -> {tradeCountryName} | L27: =IF(H27=0,"","宁波") | M27: =IF(H27=0,"","照章征税")
C28: =INDEX(商检明细!$A$17:$V$100,A27,2) -> 0 | E28: =INDEX(商检明细!$A$17:$Y$64,A27,25) -> 0 | F28: =IF(E28=0,"","千克")
C29: =INDEX(商检明细!$A$17:$V$100,A27,4) -> 0
A30: 5 | C30: =INDEX(商检明细!$A$17:$V$100,A30,3) -> 0 | E30: =INDEX(商检明细!$A$17:$Y$64,A30,5) -> 0 | F30: =INDEX(商检明细!$A$17:$Y$64,A30,8) -> 0 | G30: =INDEX(商检明细!$A$17:$Y$64,A30,6) -> 0 | H30: =INDEX(商检明细!$A$17:$Y$64,A30,7) -> 0 | I30: =IF(H30=0,"","美元") | J30: =IF(H30=0,"","中国") | K30: =G$10 -> {tradeCountryName} | L30: =IF(H30=0,"","宁波") | M30: =IF(H30=0,"","照章征税")
E31: =INDEX(商检明细!$A$17:$Y$64,A30,25) -> 0 | F31: =IF(E31=0,"","千克")
A33: 6 | C33: =INDEX(商检明细!$A$17:$V$100,A33,3) -> 0 | E33: =INDEX(商检明细!$A$17:$Y$64,A33,5) -> 0 | F33: =INDEX(商检明细!$A$17:$Y$64,A33,8) -> 0 | G33: =商检明细!M22 -> 0 | H33: =INDEX(商检明细!$A$17:$Y$64,A33,7) -> 0 | I33: =IF(H33=0,"","美元") | J33: =IF(H33=0,"","中国") | K33: =G$10 -> {tradeCountryName} | L33: =IF(H33=0,"","宁波") | M33: =IF(H33=0,"","照章征税")
C34: =INDEX(商检明细!$A$17:$V$100,A33,2) -> 0 | E34: =INDEX(商检明细!$A$17:$Y$64,A33,25) -> 0 | F34: =IF(E34=0,"","千克")
C35: =INDEX(商检明细!$A$17:$V$100,A33,4) -> 0
A36: 7 | C36: =INDEX(商检明细!$A$17:$V$100,A36,3) -> 0 | E36: =INDEX(商检明细!$A$17:$Y$64,A36,5) -> 0 | F36: =INDEX(商检明细!$A$17:$Y$64,A36,8) -> 0 | G36: =商检明细!M23 -> 0 | H36: =INDEX(商检明细!$A$17:$Y$64,A36,7) -> 0 | I36: =IF(H36=0,"","美元") | J36: =IF(H36=0,"","中国") | K36: =G$10 -> {tradeCountryName} | L36: =IF(H36=0,"","宁波") | M36: =IF(H36=0,"","照章征税")
E37: =INDEX(商检明细!$A$17:$Y$64,A36,25) -> 0 | F37: =IF(E37=0,"","千克")
A39: 8 | C39: =INDEX(商检明细!$A$17:$V$100,A39,3) -> 0 | E39: =INDEX(商检明细!$A$17:$Y$64,A39,5) -> 0 | F39: =INDEX(商检明细!$A$17:$Y$64,A39,8) -> 0 | G39: =商检明细!M24 -> 0 | H39: =INDEX(商检明细!$A$17:$Y$64,A39,7) -> 0 | I39: =IF(H39=0,"","美元") | J39: =IF(H39=0,"","中国") | K39: =G$10 -> {tradeCountryName} | L39: =IF(H39=0,"","宁波") | M39: =IF(H39=0,"","照章征税")
C40: =INDEX(商检明细!$A$17:$V$100,A39,2) -> 0 | E40: =INDEX(商检明细!$A$17:$Y$64,A39,25) -> 0 | F40: =IF(E40=0,"","千克")
C41: =INDEX(商检明细!$A$17:$V$100,A39,4) -> 0
A42: 9 | C42: =INDEX(商检明细!$A$17:$V$100,A42,3) -> 0 | E42: =INDEX(商检明细!$A$17:$Y$64,A42,5) -> 0 | F42: =INDEX(商检明细!$A$17:$Y$64,A42,8) -> 0 | G42: =商检明细!M25 -> 0 | H42: =INDEX(商检明细!$A$17:$Y$64,A42,7) -> 0 | I42: =IF(H42=0,"","美元") | J42: =IF(H42=0,"","中国") | K42: =G$10 -> {tradeCountryName} | L42: =IF(H42=0,"","宁波") | M42: =IF(H42=0,"","照章征税")
C43: =INDEX(商检明细!$A$17:$V$100,A42,2) -> 0 | E43: =INDEX(商检明细!$A$17:$Y$64,A42,25) -> 0 | F43: =IF(E43=0,"","千克")
C44: =INDEX(商检明细!$A$17:$V$100,A42,4) -> 0
A45: 特殊关系确认：否 | D45: 价格影响确认：否 | G45: 支付特许权使用费确认：否 | K45: 自报自缴：
...

Sheet 报关合同
B1: =商检明细!B13 -> {companyTitle}
B2: =VLOOKUP(B1,资料!A3:D8,2,0) -> #N/A
B3: SALES CONTRACT
B5: CONTRACT NO.: | C5: =商检明细!B5 -> {saleContractCode} | E5: DATE： | F5: =LEFT(商检明细!F3,10) -> {inputDate
B7: THE BUYER: | C7: =商检明细!H5 -> {custName}
B9: This contract is made by and between the buyers and sellers according to the terms and
B10: conditions stipulate below:
B11: Commodity and specification | D11: Quantity | F11: Unit price | G11: Amount
F12: FOB Ningbo
B13: =商检明细!C17 -> {.customsDeclarationNameEng} | D13: =商检明细!E17 -> {.declarationQuantity} | E13: =IF(D13=0,"","PCS") -> PCS | F13: =商检明细!F17 -> {.saleUnitPriceAmount} | G13: =商检明细!G17 -> {.saleAmountAmount}
B14: =商检明细!C18 -> 0 | D14: =商检明细!E18 -> 0 | E14: =IF(D14=0,"","PCS") | F14: =商检明细!F18 -> 0 | G14: =商检明细!G18 -> 0
B15: =商检明细!C19 -> 0 | D15: =商检明细!E19 -> 0 | E15: =IF(D15=0,"","PCS") | F15: =商检明细!F19 -> 0 | G15: =商检明细!G19 -> 0
B16: =商检明细!C20 -> 0 | D16: =商检明细!E20 -> 0 | E16: =IF(D16=0,"","PCS") | F16: =商检明细!F20 -> 0 | G16: =商检明细!G20 -> 0
B17: =商检明细!C21 -> 0 | D17: =商检明细!E21 -> 0 | E17: =IF(D17=0,"","PCS") | F17: =商检明细!F21 -> 0 | G17: =商检明细!G21 -> 0
B18: =商检明细!C22 -> 0 | D18: =商检明细!E22 -> 0 | E18: =IF(D18=0,"","PCS") | F18: =商检明细!F22 -> 0 | G18: =商检明细!G22 -> 0
B19: =商检明细!C23 -> 0 | D19: =商检明细!E23 -> 0 | E19: =IF(D19=0,"","PCS") | F19: =商检明细!F23 -> 0 | G19: =商检明细!G23 -> 0
B20: =商检明细!C24 -> 0 | D20: =商检明细!E24 -> 0 | E20: =IF(D20=0,"","PCS") | F20: =商检明细!F24 -> 0 | G20: =商检明细!G24 -> 0
B21: =商检明细!C25 -> 0 | D21: =商检明细!E25 -> 0 | E21: =IF(D21=0,"","PCS") | F21: =商检明细!F25 -> 0 | G21: =商检明细!G25 -> 0
B22: =商检明细!C26 -> 0 | D22: =商检明细!E26 -> 0 | E22: =IF(D22=0,"","PCS") | F22: =商检明细!F26 -> 0 | G22: =商检明细!G26 -> 0
B23: =商检明细!C27 -> 0 | D23: =商检明细!E27 -> 0 | E23: =IF(D23=0,"","PCS") | F23: =商检明细!F27 -> 0 | G23: =商检明细!G27 -> 0
B24: =商检明细!C28 -> 0 | D24: =商检明细!E28 -> 0 | E24: =IF(D24=0,"","PCS") | F24: =商检明细!F28 -> 0 | G24: =商检明细!G28 -> 0
B25: =商检明细!C29 -> 0 | E25: =IF(D25=0,"","PCS") | F25: TOTAL: | G25: =SUM(G13:G24) -> 0
B27: 1.More or less: with 5 % more or less both in amount & quantity allowed at the seller’s option.
B28: 2.SHIPMENT DATE: BEFROE | D28: =LEFT(商检明细!H4,10) -> {shipDate}
B29: ="3.FROM "&商检明细!D8&" TO "&商检明细!F8&" "&商检明细!B8 -> 3.FROM {departurePortName} TO {destinationPortName} {transportType}
B30: 4.Insurance: ( X )to be effected by the buyers
B31: ( ) to be effected by the seller for 100% of invoice value against
B32: F.P.A.W.ALLrisks and War Risk as per C.I.C. dated 1/1/1981
B33: 5.Terms of payment:
B34: ( X ) T/T ( ) L/C ( ) D/P
B35: 6.Shipping marks:
B39: 7.Special clause:
B43: THE SELLERS | E43: THE BUYERS
B44: Manager( or representative) | E44: Manager(or representative)

Sheet 资料
A2: 中文名 | B2: 英文名 | C2: 英文地址 | D2: 中文地址 | E2: BANK DETAILS | F2: 海关编码 | G2: 企业编码 | H2: 姓名 | I2: 叶群飞
A3: 宁波泛太机电有限公司 | B3: NINGBO VERTAK MECHANICAL & ELECTRONIC CO.,LTD. | C3: ADD:# 288 Guangming Road Zhuangshi Zhenhai District Ningbo, China | D3: 宁波镇海庄市街道光明路288号 | E3: BANK NAME:BANK OF NINGBO ADD:NO.700 NINGNAN SOUTH ROAD,NINGBO,P.R.CHINA,315100 SWIFT :BKNBCN2N BEBEFICIATY：NINGBO VERTAK IMP AND EXP CO.,LTD ACCT.NO.：52012029000021679 ADDRESS: NO.11 GANGDONG ROAD, EAST AREA NINGBO FREE TRADE ZONE,NINGBO CHINA | F3: 3302941306 | G3: 91330211756280575H | H3: 电话 | I3: 0574-55833538
H4: 邮箱 | I4: yequnfei@vertak.com
H5: 传真 | I5: 0574-55877673
H7: 姓名 | I7: 姚磊艳
H8: 电话 | I8: 0574-55833539
H9: 邮箱 | I9: laura.yao@vertak.com
H10: 传真 | I10: 0574-55877673
H12: 姓名 | I12: 林清
H13: 电话 | I13: 0574-55833537
H14: 邮箱 | I14: linqing@vertak.com
H15: 传真 | I15: 0574-55877673
A34: CNY | B34: 人民币
A35: GBP | B35: 英镑
A36: JPY | B36: 日元
A37: EUR | B37: 欧元
A38: HKD | B38: 港币
A39: RMB | B39: 人民币
A40: USD | B40: 美元
