Workbook

Sheet 报关明细
A1: 报关单
A2: 基本信息
A3: 发票号 | B3: {invoiceCode} | C3: 单据编号 | D3: {code} | E3: 制单日期 | F3: {inputDate} | G3: 状态名称 | H3: {status}
A4: 录入人 | B4: {inputUserName} | C4: 审核时间 | E4: 审核人 | G4: 出运日期 | H4: {shipDate}
A5: 外销合同 | B5: {saleContractCode} | C5: 客户合同 | D5: {custPo} | E5: 外销币种 | F5: {currency} | G5: 贸易国别 | H5: {tradeCountryName}
A6: 客户编号 | B6: {custCode} | C6: 客户名称 | D6: {custName} | E6: 贸易方式 | F6: {tradeType} | G6: 价格条款 | H6: {settlementTermType}
A7: 结汇方式 | B7: {settlementName} | C7: 结汇方式名称 | E7: 船代公司 | F7: {forwarderCompanyName} | G7: 集装箱数量 | H7: {containerQuantity}
A8: 运输方式 | B8: {transportType} | C8: 出运口岸 | D8: {departurePortName} | E8: 目的口岸 | F8: {destinationPortName}
A9: 合计
A10: 数量合计 | B10: {totalQuantity} | C10: 箱数合计 | D10: {totalBoxes} | E10: 毛重合计 | F10: {totalGrossweight} | G10: 净重合计 | H10: {totalWeight}
A11: 体积合计 | B11: {totalVolume} | C11: 金额合计 | D11: {totalAmount}
A12: 备注信息
A13: 抬头人 | B13: {companyTitle} | C13: 备注 | D13: {remark} | E13: 收货人 | F13: {receivePerson} | G13: 通知人 | H13: {notifyPerson}
A14: 正面唛头 | B14: {frontShippingMark}
A16: 序号 | B16: 海关编码 | C16: 报关要素 | D16: 中文品名 | E16: 英文品名 | F16: 出货数量 | G16: 计量单位 | H16: 海关计量单位 | I16: 报关数量 | J16: 箱数 | K16: 外箱单位 | L16: 计价方式 | M16: 报关单价 | N16: 报关总价 | O16: 外箱体积 | P16: 总体积 | Q16: 外箱毛重 | R16: 总毛重 | S16: 外箱净重 | T16: 总净重 | U16: 退税率% | V16: 客户合同
A17: {.sortNum} | B17: {.hsCode} | C17: {.customsDeclareElements} | D17: {.declarationName} | E17: {.customsDeclarationNameEng} | F17: {.shippingQuantity} | G17: {.declarationUnit} | H17: {.hsMeasureUnit} | I17: {.declarationQuantity} | J17: {.boxCount} | K17: {.unitPerOuterbox} | L17: {.pricingMethod} | M17: {.declarationUnitPriceAmount} | N17: {.declarationTotalPrice} | O17: {.outerboxVolume} | P17: {.totalVolume} | Q17: {.outerboxGrossweightweight} | R17: {.totalGrossweightweight} | S17: {.outerboxNetweightweight} | T17: {.totalNetweightweight} | U17: {.taxRefundRate} | V17: {.cskuCode}

Sheet 报关发票
A1: =报关明细!B13 -> {companyTitle}
A2: =VLOOKUP(A1,资料!A3:D8,2,0) -> #N/A
A3: =VLOOKUP(A1,资料!A3:D8,3,0) -> #N/A
A5: COMMERCIAL INVOICE
A7: 付款方式 | E7: 发票号码 | G7: =报关明细!B3 -> {invoiceCode}
A8: PAYMENT | E8: INV.NO.
A10: 合同号码 | B10: =报关明细!B5 -> {saleContractCode} | E10: 日 期 | G10: =LEFT(报关明细!F3,10) -> {inputDate
A11: CONTRACT NO. | E11: DATE:
A13: 客 户 | B13: =报关明细!D6 -> {custName}
A14: MESSRS
A16: 地 址
A17: ADDRESS
A19: 船 由 | B19: =报关明细!B8 -> {transportType}
A20: FROM
B22: 货 名 | C22: 件 数 | E22: 数 量 | G22: 单 价 | I22: 金 额
B23: DESCRIPTION | C23: PKG | E23: QTY | G23: UNIT PRICE | I23: AMOUNT
G24: =报关明细!H6&" "&报关明细!D8 -> {settlementTermType} {departurePortName}
B25: =INDEX(报关明细!$A$17:$V$101,ROW()-24,5) -> {.customsDeclarationNameEng} | C25: =INDEX(报关明细!$A$17:$V$101,ROW()-24,10) -> {.boxCount} | D25: =INDEX(报关明细!$A$17:$V$101,ROW()-24,11) -> {.unitPerOuterbox} | E25: =INDEX(报关明细!$A$17:$V$101,ROW()-24,9) -> {.declarationQuantity} | F25: =IF(E25=0,"","PCS") -> PCS | G25: =报关明细!F5 -> {currency} | H25: =INDEX(报关明细!$A$17:$V$101,ROW()-24,13) -> {.declarationUnitPriceAmount} | I25: =报关明细!F5 -> {currency} | J25: =INDEX(报关明细!$A$17:$V$101,ROW()-24,14) -> {.declarationTotalPrice}
B26: =INDEX(报关明细!$A$17:$V$101,ROW()-24,5) -> 0 | C26: =INDEX(报关明细!$A$17:$V$101,ROW()-24,10) -> 0 | D26: =INDEX(报关明细!$A$17:$V$101,ROW()-24,11) -> 0 | E26: =INDEX(报关明细!$A$17:$V$101,ROW()-24,9) -> 0 | F26: =IF(E26=0,"","PCS") | G26: =IF(H26=0,"",$G$25) | H26: =INDEX(报关明细!$A$17:$V$101,ROW()-24,13) -> 0 | I26: =IF(J26=0,"",$I$25) | J26: =INDEX(报关明细!$A$17:$V$101,ROW()-24,14) -> 0
B27: =INDEX(报关明细!$A$17:$V$101,ROW()-24,5) -> 0 | C27: =INDEX(报关明细!$A$17:$V$101,ROW()-24,10) -> 0 | D27: =INDEX(报关明细!$A$17:$V$101,ROW()-24,11) -> 0 | E27: =INDEX(报关明细!$A$17:$V$101,ROW()-24,9) -> 0 | F27: =IF(E27=0,"","PCS") | G27: =IF(H27=0,"",$G$25) | H27: =INDEX(报关明细!$A$17:$V$101,ROW()-24,13) -> 0 | I27: =IF(J27=0,"",$I$25) | J27: =INDEX(报关明细!$A$17:$V$101,ROW()-24,14) -> 0
B28: =INDEX(报关明细!$A$17:$V$101,ROW()-24,5) -> 0 | C28: =INDEX(报关明细!$A$17:$V$101,ROW()-24,10) -> 0 | D28: =INDEX(报关明细!$A$17:$V$101,ROW()-24,11) -> 0 | E28: =INDEX(报关明细!$A$17:$V$101,ROW()-24,9) -> 0 | F28: =IF(E28=0,"","PCS") | G28: =IF(H28=0,"",$G$25) | H28: =INDEX(报关明细!$A$17:$V$101,ROW()-24,13) -> 0 | I28: =IF(J28=0,"",$I$25) | J28: =INDEX(报关明细!$A$17:$V$101,ROW()-24,14) -> 0
B29: =INDEX(报关明细!$A$17:$V$101,ROW()-24,5) -> 0 | C29: =INDEX(报关明细!$A$17:$V$101,ROW()-24,10) -> 0 | D29: =INDEX(报关明细!$A$17:$V$101,ROW()-24,11) -> 0 | E29: =INDEX(报关明细!$A$17:$V$101,ROW()-24,9) -> 0 | F29: =IF(E29=0,"","PCS") | G29: =IF(H29=0,"",$G$25) | H29: =INDEX(报关明细!$A$17:$V$101,ROW()-24,13) -> 0 | I29: =IF(J29=0,"",$I$25) | J29: =INDEX(报关明细!$A$17:$V$101,ROW()-24,14) -> 0
B30: =INDEX(报关明细!$A$17:$V$101,ROW()-24,5) -> 0 | C30: =INDEX(报关明细!$A$17:$V$101,ROW()-24,10) -> 0 | D30: =INDEX(报关明细!$A$17:$V$101,ROW()-24,11) -> 0 | E30: =INDEX(报关明细!$A$17:$V$101,ROW()-24,9) -> 0 | F30: =IF(E30=0,"","PCS") | G30: =IF(H30=0,"",$G$25) | H30: =INDEX(报关明细!$A$17:$V$101,ROW()-24,13) -> 0 | I30: =IF(J30=0,"",$I$25) | J30: =INDEX(报关明细!$A$17:$V$101,ROW()-24,14) -> 0
B31: =INDEX(报关明细!$A$17:$V$101,ROW()-24,5) -> 0 | C31: =INDEX(报关明细!$A$17:$V$101,ROW()-24,10) -> 0 | D31: =INDEX(报关明细!$A$17:$V$101,ROW()-24,11) -> 0 | E31: =INDEX(报关明细!$A$17:$V$101,ROW()-24,9) -> 0 | F31: =IF(E31=0,"","PCS") | G31: =IF(H31=0,"",$G$25) | H31: =INDEX(报关明细!$A$17:$V$101,ROW()-24,13) -> 0 | I31: =IF(J31=0,"",$I$25) | J31: =INDEX(报关明细!$A$17:$V$101,ROW()-24,14) -> 0
B32: =INDEX(报关明细!$A$17:$V$101,ROW()-24,5) -> 0 | C32: =INDEX(报关明细!$A$17:$V$101,ROW()-24,10) -> 0 | D32: =INDEX(报关明细!$A$17:$V$101,ROW()-24,11) -> 0 | E32: =INDEX(报关明细!$A$17:$V$101,ROW()-24,9) -> 0 | F32: =IF(E32=0,"","PCS") | G32: =IF(H32=0,"",$G$25) | H32: =INDEX(报关明细!$A$17:$V$101,ROW()-24,13) -> 0 | I32: =IF(J32=0,"",$I$25) | J32: =INDEX(报关明细!$A$17:$V$101,ROW()-24,14) -> 0
B33: =INDEX(报关明细!$A$17:$V$101,ROW()-24,5) -> 0 | C33: =INDEX(报关明细!$A$17:$V$101,ROW()-24,10) -> 0 | D33: =INDEX(报关明细!$A$17:$V$101,ROW()-24,11) -> 0 | E33: =INDEX(报关明细!$A$17:$V$101,ROW()-24,9) -> 0 | F33: =IF(E33=0,"","PCS") | G33: =IF(H33=0,"",$G$25) | H33: =INDEX(报关明细!$A$17:$V$101,ROW()-24,13) -> 0 | I33: =IF(J33=0,"",$I$25) | J33: =INDEX(报关明细!$A$17:$V$101,ROW()-24,14) -> 0
B34: =INDEX(报关明细!$A$17:$V$101,ROW()-24,5) -> 0 | C34: =INDEX(报关明细!$A$17:$V$101,ROW()-24,10) -> 0 | D34: =INDEX(报关明细!$A$17:$V$101,ROW()-24,11) -> 0 | E34: =INDEX(报关明细!$A$17:$V$101,ROW()-24,9) -> 0 | F34: =IF(E34=0,"","PCS") | G34: =IF(H34=0,"",$G$25) | H34: =INDEX(报关明细!$A$17:$V$101,ROW()-24,13) -> 0 | I34: =IF(J34=0,"",$I$25) | J34: =INDEX(报关明细!$A$17:$V$101,ROW()-24,14) -> 0
B35: =INDEX(报关明细!$A$17:$V$101,11,5) -> 0 | C35: =INDEX(报关明细!$A$17:$V$101,ROW()-24,10) -> 0 | D35: =INDEX(报关明细!$A$17:$V$101,ROW()-24,11) -> 0 | E35: =INDEX(报关明细!$A$17:$V$101,ROW()-24,9) -> 0 | F35: =IF(E35=0,"","PCS") | G35: =IF(H35=0,"",$G$25) | H35: =INDEX(报关明细!$A$17:$V$101,ROW()-24,13) -> 0 | I35: =IF(J35=0,"",$I$25) | J35: =INDEX(报关明细!$A$17:$V$101,ROW()-24,14) -> 0
B36: TOTAL: | C36: =SUM(C25:C35) -> 0 | D36: CTNS | E36: =SUM(E25:E35) -> 0 | F36: PCS | H36: =SUM(I25:I35) -> 0 | I36: =I25 -> {currency} | J36: =SUM(J25:J35) -> 0
A37: =报关明细!B14 -> {frontShippingMark}

Sheet 报关箱单
A1: =报关明细!B13 -> {companyTitle}
A2: =VLOOKUP(A1,资料!A3:D8,2,0) -> #N/A
A3: =VLOOKUP(A1,资料!A3:D8,3,0) -> #N/A
A5: PACKING LIST
A6: 付款方式 | F6: 发票号码 | H6: =报关明细!B3 -> {invoiceCode}
A7: PAYMENT | F7: INV.NO.
A8: 合同号码 | B8: =报关明细!B5 -> {saleContractCode} | F8: 日 期 | H8: =LEFT(报关明细!F3,10) -> {inputDate
A9: CONTRACT NO. | F9: DATE:
A10: 客 户 | B10: =报关明细!D6 -> {custName}
A11: MESSRS
A12: 地 址
A13: ADDRESS
A14: 船 由 | B14: =报关明细!B8 -> {transportType}
A15: FROM
B16: 货 名 | C16: 件 数 | E16: 数 量 | G16: 毛 重 | H16: 净 重 | I16: 体 积
B17: DESCRIPTION | C17: PKG | E17: QTY | G17: G.W. | H17: N.W. | I17: MEAS.
G18: KGS | H18: KGS | I18: CBM
B20: =INDEX(报关明细!$A$17:$V$101,ROW()-19,5) -> {.customsDeclarationNameEng} | C20: =INDEX(报关明细!$A$17:$V$101,ROW()-19,10) -> {.boxCount} | D20: =INDEX(报关明细!$A$17:$V$101,ROW()-19,11) -> {.unitPerOuterbox} | E20: =INDEX(报关明细!$A$17:$V$101,ROW()-19,9) -> {.declarationQuantity} | F20: =IF(E20=0,"","PCS") -> PCS | G20: =INDEX(报关明细!$A$17:$V$101,ROW()-19,18) -> {.totalGrossweightweight} | H20: =INDEX(报关明细!$A$17:$V$101,ROW()-19,20) -> {.totalNetweightweight} | I20: =INDEX(报关明细!$A$17:$V$101,ROW()-19,16) -> {.totalVolume}
B21: =INDEX(报关明细!$A$17:$V$101,ROW()-19,5) -> 0 | C21: =INDEX(报关明细!$A$17:$V$101,ROW()-19,10) -> 0 | D21: =INDEX(报关明细!$A$17:$V$101,ROW()-19,11) -> 0 | E21: =INDEX(报关明细!$A$17:$V$101,ROW()-19,9) -> 0 | F21: =IF(E21=0,"","PCS") | G21: =INDEX(报关明细!$A$17:$V$101,ROW()-19,18) -> 0 | H21: =INDEX(报关明细!$A$17:$V$101,ROW()-19,20) -> 0 | I21: =INDEX(报关明细!$A$17:$V$101,ROW()-19,16) -> 0
B22: =INDEX(报关明细!$A$17:$V$101,ROW()-19,5) -> 0 | C22: =INDEX(报关明细!$A$17:$V$101,ROW()-19,10) -> 0 | D22: =INDEX(报关明细!$A$17:$V$101,ROW()-19,11) -> 0 | E22: =INDEX(报关明细!$A$17:$V$101,ROW()-19,9) -> 0 | F22: =IF(E22=0,"","PCS") | G22: =INDEX(报关明细!$A$17:$V$101,ROW()-19,18) -> 0 | H22: =INDEX(报关明细!$A$17:$V$101,ROW()-19,20) -> 0 | I22: =INDEX(报关明细!$A$17:$V$101,ROW()-19,16) -> 0
B23: =INDEX(报关明细!$A$17:$V$101,ROW()-19,5) -> 0 | C23: =INDEX(报关明细!$A$17:$V$101,ROW()-19,10) -> 0 | D23: =INDEX(报关明细!$A$17:$V$101,ROW()-19,11) -> 0 | E23: =INDEX(报关明细!$A$17:$V$101,ROW()-19,9) -> 0 | F23: =IF(E23=0,"","PCS") | G23: =INDEX(报关明细!$A$17:$V$101,ROW()-19,18) -> 0 | H23: =INDEX(报关明细!$A$17:$V$101,ROW()-19,20) -> 0 | I23: =INDEX(报关明细!$A$17:$V$101,ROW()-19,16) -> 0
B24: =INDEX(报关明细!$A$17:$V$101,ROW()-19,5) -> 0 | C24: =INDEX(报关明细!$A$17:$V$101,ROW()-19,10) -> 0 | D24: =INDEX(报关明细!$A$17:$V$101,ROW()-19,11) -> 0 | E24: =INDEX(报关明细!$A$17:$V$101,ROW()-19,9) -> 0 | F24: =IF(E24=0,"","PCS") | G24: =INDEX(报关明细!$A$17:$V$101,ROW()-19,18) -> 0 | H24: =INDEX(报关明细!$A$17:$V$101,ROW()-19,20) -> 0 | I24: =INDEX(报关明细!$A$17:$V$101,ROW()-19,16) -> 0
B25: =INDEX(报关明细!$A$17:$V$101,ROW()-19,5) -> 0 | C25: =INDEX(报关明细!$A$17:$V$101,ROW()-19,10) -> 0 | D25: =INDEX(报关明细!$A$17:$V$101,ROW()-19,11) -> 0 | E25: =INDEX(报关明细!$A$17:$V$101,ROW()-19,9) -> 0 | F25: =IF(E25=0,"","PCS") | G25: =INDEX(报关明细!$A$17:$V$101,ROW()-19,18) -> 0 | H25: =INDEX(报关明细!$A$17:$V$101,ROW()-19,20) -> 0 | I25: =INDEX(报关明细!$A$17:$V$101,ROW()-19,16) -> 0
B26: =INDEX(报关明细!$A$17:$V$101,ROW()-19,5) -> 0 | C26: =INDEX(报关明细!$A$17:$V$101,ROW()-19,10) -> 0 | D26: =INDEX(报关明细!$A$17:$V$101,ROW()-19,11) -> 0 | E26: =INDEX(报关明细!$A$17:$V$101,ROW()-19,9) -> 0 | F26: =IF(E26=0,"","PCS") | G26: =INDEX(报关明细!$A$17:$V$101,ROW()-19,18) -> 0 | H26: =INDEX(报关明细!$A$17:$V$101,ROW()-19,20) -> 0 | I26: =INDEX(报关明细!$A$17:$V$101,ROW()-19,16) -> 0
B27: =INDEX(报关明细!$A$17:$V$101,ROW()-19,5) -> 0 | C27: =INDEX(报关明细!$A$17:$V$101,ROW()-19,10) -> 0 | D27: =INDEX(报关明细!$A$17:$V$101,ROW()-19,11) -> 0 | E27: =INDEX(报关明细!$A$17:$V$101,ROW()-19,9) -> 0 | F27: =IF(E27=0,"","PCS") | G27: =INDEX(报关明细!$A$17:$V$101,ROW()-19,18) -> 0 | H27: =INDEX(报关明细!$A$17:$V$101,ROW()-19,20) -> 0 | I27: =INDEX(报关明细!$A$17:$V$101,ROW()-19,16) -> 0
B28: =INDEX(报关明细!$A$17:$V$101,ROW()-19,5) -> 0 | C28: =INDEX(报关明细!$A$17:$V$101,ROW()-19,10) -> 0 | D28: =INDEX(报关明细!$A$17:$V$101,ROW()-19,11) -> 0 | E28: =INDEX(报关明细!$A$17:$V$101,ROW()-19,9) -> 0 | F28: =IF(E28=0,"","PCS") | G28: =INDEX(报关明细!$A$17:$V$101,ROW()-19,18) -> 0 | H28: =INDEX(报关明细!$A$17:$V$101,ROW()-19,20) -> 0 | I28: =INDEX(报关明细!$A$17:$V$101,ROW()-19,16) -> 0
B29: =INDEX(报关明细!$A$17:$V$101,ROW()-19,5) -> 0 | C29: =INDEX(报关明细!$A$17:$V$101,ROW()-19,10) -> 0 | D29: =INDEX(报关明细!$A$17:$V$101,ROW()-19,11) -> 0 | E29: =INDEX(报关明细!$A$17:$V$101,ROW()-19,9) -> 0 | F29: =IF(E29=0,"","PCS") | G29: =INDEX(报关明细!$A$17:$V$101,ROW()-19,18) -> 0 | H29: =INDEX(报关明细!$A$17:$V$101,ROW()-19,20) -> 0 | I29: =INDEX(报关明细!$A$17:$V$101,ROW()-19,16) -> 0
B30: =INDEX(报关明细!$A$17:$V$101,ROW()-19,5) -> 0 | C30: =INDEX(报关明细!$A$17:$V$101,ROW()-19,10) -> 0 | D30: =INDEX(报关明细!$A$17:$V$101,ROW()-19,11) -> 0 | E30: =INDEX(报关明细!$A$17:$V$101,ROW()-19,9) -> 0 | F30: =IF(E30=0,"","PCS") | G30: =INDEX(报关明细!$A$17:$V$101,ROW()-19,18) -> 0 | H30: =INDEX(报关明细!$A$17:$V$101,ROW()-19,20) -> 0 | I30: =INDEX(报关明细!$A$17:$V$101,ROW()-19,16) -> 0
B31: TOTAL: | C31: =SUM(C20:C30) -> 0 | D31: CTNS | E31: =SUM(E20:E30) -> 0 | F31: PCS | G31: =SUM(G20:G30) -> 0 | H31: =SUM(H20:H30) -> 0 | I31: =SUM(I20:I30) -> 0
A34: =报关明细!B14 -> {frontShippingMark}

Sheet 报关单
A1: 中华人民共和国海关出口货物报关单（最新版）
A2: 预录入编号: | D2: 海关编号: | I2: 页码/页数：
A3: 境内发货人 | G3: 出境关别 | I3: 出口日期 | K3: 申报日期 | L3: 备案号
A4: =VLOOKUP(D4,资料!A3:G8,7,0) -> #N/A | C4: =VLOOKUP(D4,资料!A3:G8,6,0) -> #N/A | D4: =报关明细!B13 -> {companyTitle} | G4: 宁波海关 | I4: =LEFT(报关明细!H4,10) -> {shipDate}
A5: 境外收货人 | G5: 运输方式 | I5: 运输工具名称及航次号 | K5: 提运单号
A6: =报关明细!D6 -> {custName} | G6: =报关明细!B8 -> {transportType}
A7: 生产销售单位 | G7: 监管方式 | I7: 征免性质 | K7: 许可证号
A8: =VLOOKUP(D8,资料!A3:G8,7,0) -> #N/A | C8: =VLOOKUP(D8,资料!A3:G8,6,0) -> #N/A | D8: =报关明细!B13 -> {companyTitle} | G8: 一般贸易 | I8: 一般征税
A9: 合同协议号 | D9: 贸易国（地区） | G9: 运抵国（地区） | K9: 指运港 | L9: 离境口岸
A10: =报关明细!B5 -> {saleContractCode} | D10: =报关明细!H5 -> {tradeCountryName} | G10: =报关明细!H5 -> {tradeCountryName} | K10: =报关明细!F8 -> {destinationPortName} | L10: =报关明细!D8 -> {departurePortName}
A11: 运输包装种类 | C11: 件数 | D11: 其他包装种类及对应数量 | E11: 毛重（千克） | G11: 净重（千克） | H11: 成交方式 | I11: 运费（金额、币制） | K11: 保费（金额、币制） | M11: 杂费（金额、币制）
A12: 纸箱 | C12: =报关明细!D10&"CTNS" -> {totalBoxes}CTNS | E12: =报关明细!F10 -> {totalGrossweight} | G12: =报关明细!H10 -> {totalWeight} | H12: FOB
A13: 随附单证及编号
A15: 标记唛码及备注
A17: 项号 | B17: 商品编号 | C17: 商品名称 | E17: 数量 | F17: 单位 | G17: 单价 | H17: 总价 | I17: 币制 | J17: 原产国（地区） | K17: 最终目的国（地区） | L17: 境内货源地 | M17: 征免
A18: 1 | B18: =INDEX(报关明细!$A$17:$V$101,A18,2) -> {.hsCode} | C18: =INDEX(报关明细!$A$17:$V$101,A18,4) -> {.declarationName} | E18: =INDEX(报关明细!$A$17:$V$101,A18,9) -> {.declarationQuantity} | F18: =INDEX(报关明细!$A$17:$V$101,A18,8) -> {.hsMeasureUnit} | G18: =INDEX(报关明细!$A$17:$V$101,A18,13) -> {.declarationUnitPriceAmount} | H18: =INDEX(报关明细!$A$17:$V$101,A18,14) -> {.declarationTotalPrice} | I18: =VLOOKUP(报关明细!F5,资料!A34:B40,2,0) -> #N/A | J18: =IF(H18=0,"","中国") -> 中国 | K18: =报关明细!H5 -> {tradeCountryName} | L18: =IF(H18=0,"","宁波") -> 宁波 | M18: =IF(H18=0,"","照章征税") -> 照章征税
C19: =INDEX(报关明细!$A$17:$V$101,A18,5) -> {.customsDeclarationNameEng} | E19: =INDEX(报关明细!$A$17:$V$101,A18,20) -> {.totalNetweightweight} | F19: =IF(E19=0,"","千克") -> 千克
C20: =INDEX(报关明细!$A$17:$V$101,A18,3) -> {.customsDeclareElements}
A21: 2 | B21: =INDEX(报关明细!$A$17:$V$101,A21,2) -> 0 | C21: =INDEX(报关明细!$A$17:$V$101,A21,4) -> 0 | E21: =INDEX(报关明细!$A$17:$V$101,A21,9) -> 0 | F21: =INDEX(报关明细!$A$17:$V$101,A21,8) -> 0 | G21: =INDEX(报关明细!$A$17:$V$101,A21,13) -> 0 | H21: =INDEX(报关明细!$A$17:$V$101,A21,14) -> 0 | I21: =IF(H21=0,"",I18) | J21: =IF(H21=0,"","中国") | K21: =IF(H21=0,"",K18) | L21: =IF(H21=0,"","宁波") | M21: =IF(H21=0,"","照章征税")
C22: =INDEX(报关明细!$A$17:$V$101,A21,5) -> 0 | E22: =INDEX(报关明细!$A$17:$V$101,A21,20) -> 0 | F22: =IF(E22=0,"","千克")
C23: =INDEX(报关明细!$A$17:$V$101,A21,3) -> 0
A24: 3 | B24: =INDEX(报关明细!$A$17:$V$101,A24,2) -> 0 | C24: =INDEX(报关明细!$A$17:$V$101,A24,4) -> 0 | E24: =INDEX(报关明细!$A$17:$V$101,A24,9) -> 0 | F24: =INDEX(报关明细!$A$17:$V$101,A24,8) -> 0 | G24: =INDEX(报关明细!$A$17:$V$101,A24,13) -> 0 | H24: =INDEX(报关明细!$A$17:$V$101,A24,14) -> 0 | I24: =IF(H24=0,"",I21) | J24: =IF(H24=0,"","中国") | K24: =IF(H24=0,"",K21) | L24: =IF(H24=0,"","宁波") | M24: =IF(H24=0,"","照章征税")
C25: =INDEX(报关明细!$A$17:$V$101,A24,5) -> 0 | E25: =INDEX(报关明细!$A$17:$V$101,A24,20) -> 0 | F25: =IF(E25=0,"","千克")
C26: =INDEX(报关明细!$A$17:$V$101,A24,3) -> 0
A27: 4 | B27: =INDEX(报关明细!$A$17:$V$101,A27,2) -> 0 | C27: =INDEX(报关明细!$A$17:$V$101,A27,4) -> 0 | E27: =INDEX(报关明细!$A$17:$V$101,A27,9) -> 0 | F27: =INDEX(报关明细!$A$17:$V$101,A27,8) -> 0 | G27: =INDEX(报关明细!$A$17:$V$101,A27,13) -> 0 | H27: =INDEX(报关明细!$A$17:$V$101,A27,14) -> 0 | I27: =IF(H27=0,"",I24) | J27: =IF(H27=0,"","中国") | K27: =IF(H27=0,"",K24) | L27: =IF(H27=0,"","宁波") | M27: =IF(H27=0,"","照章征税")
C28: =INDEX(报关明细!$A$17:$V$101,A27,5) -> 0 | E28: =INDEX(报关明细!$A$17:$V$101,A27,20) -> 0 | F28: =IF(E28=0,"","千克")
C29: =INDEX(报关明细!$A$17:$V$101,A27,3) -> 0
A30: 5 | B30: =INDEX(报关明细!$A$17:$V$101,A30,2) -> 0 | C30: =INDEX(报关明细!$A$17:$V$101,A30,4) -> 0 | E30: =INDEX(报关明细!$A$17:$V$101,A30,9) -> 0 | F30: =INDEX(报关明细!$A$17:$V$101,A30,8) -> 0 | G30: =INDEX(报关明细!$A$17:$V$101,A30,13) -> 0 | H30: =INDEX(报关明细!$A$17:$V$101,A30,14) -> 0 | I30: =IF(H30=0,"",I27) | J30: =IF(H30=0,"","中国") | K30: =IF(H30=0,"",K27) | L30: =IF(H30=0,"","宁波") | M30: =IF(H30=0,"","照章征税")
C31: =INDEX(报关明细!$A$17:$V$101,A30,5) -> 0 | E31: =INDEX(报关明细!$A$17:$V$101,A30,20) -> 0 | F31: =IF(E31=0,"","千克")
C32: =INDEX(报关明细!$A$17:$V$101,A30,3) -> 0
A33: 6 | B33: =INDEX(报关明细!$A$17:$V$101,A33,2) -> 0 | C33: =INDEX(报关明细!$A$17:$V$101,A33,4) -> 0 | E33: =INDEX(报关明细!$A$17:$V$101,A33,9) -> 0 | F33: =INDEX(报关明细!$A$17:$V$101,A33,8) -> 0 | G33: =INDEX(报关明细!$A$17:$V$101,A33,13) -> 0 | H33: =INDEX(报关明细!$A$17:$V$101,A33,14) -> 0 | I33: =IF(H33=0,"",I30) | J33: =IF(H33=0,"","中国") | K33: =IF(H33=0,"",K30) | L33: =IF(H33=0,"","宁波") | M33: =IF(H33=0,"","照章征税")
C34: =INDEX(报关明细!$A$17:$V$101,A33,5) -> 0 | E34: =INDEX(报关明细!$A$17:$V$101,A33,20) -> 0 | F34: =IF(E34=0,"","千克")
C35: =INDEX(报关明细!$A$17:$V$101,A33,3) -> 0
A36: 7 | B36: =INDEX(报关明细!$A$17:$V$101,A36,2) -> 0 | C36: =INDEX(报关明细!$A$17:$V$101,A36,4) -> 0 | E36: =INDEX(报关明细!$A$17:$V$101,A36,9) -> 0 | F36: =INDEX(报关明细!$A$17:$V$101,A36,8) -> 0 | G36: =INDEX(报关明细!$A$17:$V$101,A36,13) -> 0 | H36: =INDEX(报关明细!$A$17:$V$101,A36,14) -> 0 | I36: =IF(H36=0,"",I33) | J36: =IF(H36=0,"","中国") | K36: =IF(H36=0,"",K33) | L36: =IF(H36=0,"","宁波") | M36: =IF(H36=0,"","照章征税")
C37: =INDEX(报关明细!$A$17:$V$101,A36,5) -> 0 | E37: =INDEX(报关明细!$A$17:$V$101,A36,20) -> 0 | F37: =IF(E37=0,"","千克")
C38: =INDEX(报关明细!$A$17:$V$101,A36,3) -> 0
A39: 8 | B39: =INDEX(报关明细!$A$17:$V$101,A39,2) -> 0 | C39: =INDEX(报关明细!$A$17:$V$101,A39,4) -> 0 | E39: =INDEX(报关明细!$A$17:$V$101,A39,9) -> 0 | F39: =INDEX(报关明细!$A$17:$V$101,A39,8) -> 0 | G39: =INDEX(报关明细!$A$17:$V$101,A39,13) -> 0 | H39: =INDEX(报关明细!$A$17:$V$101,A39,14) -> 0 | I39: =IF(H39=0,"",I36) | J39: =IF(H39=0,"","中国") | K39: =IF(H39=0,"",K36) | L39: =IF(H39=0,"","宁波") | M39: =IF(H39=0,"","照章征税")
C40: =INDEX(报关明细!$A$17:$V$101,A39,5) -> 0 | E40: =INDEX(报关明细!$A$17:$V$101,A39,20) -> 0 | F40: =IF(E40=0,"","千克")
C41: =INDEX(报关明细!$A$17:$V$101,A39,3) -> 0
A42: 9 | B42: =报关明细!B26 -> 0 | C42: =报关明细!D26 -> 0 | E42: =INDEX(报关明细!$A$17:$V$101,A42,9) -> 0 | F42: =报关明细!H26 -> 0 | G42: =INDEX(报关明细!$A$17:$V$101,A42,13) -> 0 | H42: =INDEX(报关明细!$A$17:$V$101,A42,14) -> 0 | I42: =IF(H42=0,"",I39) | J42: =IF(H42=0,"","中国") | K42: =IF(H42=0,"",K39) | L42: =IF(H42=0,"","宁波") | M42: =IF(H42=0,"","照章征税")
...

Sheet 报关合同
B1: =报关明细!B13 -> {companyTitle}
B2: =VLOOKUP(B1,资料!A3:D8,2,0) -> #N/A
B3: SALES CONTRACT
B5: CONTRACT NO.: | C5: =报关明细!B5 -> {saleContractCode} | E5: DATE： | F5: =LEFT(报关明细!F3,10) -> {inputDate
B7: THE BUYER: | C7: =报关明细!D6 -> {custName}
B9: This contract is made by and between the buyers and sellers according to the terms and
B10: conditions stipulate below: | L10: s
B11: Commodity and specification | D11: Quantity | F11: Unit price | H11: Amount
F12: =报关明细!H6&报关明细!D8 -> {settlementTermType}{departurePortName}
B13: =INDEX(报关明细!$A$17:$V$101,ROW()-12,5) -> {.customsDeclarationNameEng} | D13: =INDEX(报关明细!$A$17:$V$101,ROW()-12,9) -> {.declarationQuantity} | E13: =IF(D13=0,"","PCS") -> PCS | F13: =报关明细!F5 -> {currency} | G13: =INDEX(报关明细!$A$17:$V$101,ROW()-12,13) -> {.declarationUnitPriceAmount} | H13: =报关明细!F5 -> {currency} | I13: =INDEX(报关明细!$A$17:$V$101,ROW()-12,14) -> {.declarationTotalPrice}
B14: =INDEX(报关明细!$A$17:$V$101,ROW()-12,5) -> 0 | D14: =INDEX(报关明细!$A$17:$V$101,ROW()-12,9) -> 0 | E14: =IF(D14=0,"","PCS") | F14: =IF(G14=0,"",$F$13) | G14: =INDEX(报关明细!$A$17:$V$101,ROW()-12,13) -> 0 | H14: =IF(I14=0,"",$H$13) | I14: =INDEX(报关明细!$A$17:$V$101,ROW()-12,14) -> 0
B15: =INDEX(报关明细!$A$17:$V$101,ROW()-12,5) -> 0 | D15: =INDEX(报关明细!$A$17:$V$101,ROW()-12,9) -> 0 | E15: =IF(D15=0,"","PCS") | F15: =IF(G15=0,"",$F$13) | G15: =INDEX(报关明细!$A$17:$V$101,ROW()-12,13) -> 0 | H15: =IF(I15=0,"",$H$13) | I15: =INDEX(报关明细!$A$17:$V$101,ROW()-12,14) -> 0
B16: =INDEX(报关明细!$A$17:$V$101,ROW()-12,5) -> 0 | D16: =INDEX(报关明细!$A$17:$V$101,ROW()-12,9) -> 0 | E16: =IF(D16=0,"","PCS") | F16: =IF(G16=0,"",$F$13) | G16: =INDEX(报关明细!$A$17:$V$101,ROW()-12,13) -> 0 | H16: =IF(I16=0,"",$H$13) | I16: =INDEX(报关明细!$A$17:$V$101,ROW()-12,14) -> 0
B17: =INDEX(报关明细!$A$17:$V$101,ROW()-12,5) -> 0 | D17: =INDEX(报关明细!$A$17:$V$101,ROW()-12,9) -> 0 | E17: =IF(D17=0,"","PCS") | F17: =IF(G17=0,"",$F$13) | G17: =INDEX(报关明细!$A$17:$V$101,ROW()-12,13) -> 0 | H17: =IF(I17=0,"",$H$13) | I17: =INDEX(报关明细!$A$17:$V$101,ROW()-12,14) -> 0
B18: =INDEX(报关明细!$A$17:$V$101,ROW()-12,5) -> 0 | D18: =INDEX(报关明细!$A$17:$V$101,ROW()-12,9) -> 0 | E18: =IF(D18=0,"","PCS") | F18: =IF(G18=0,"",$F$13) | G18: =INDEX(报关明细!$A$17:$V$101,ROW()-12,13) -> 0 | H18: =IF(I18=0,"",$H$13) | I18: =INDEX(报关明细!$A$17:$V$101,ROW()-12,14) -> 0
B19: =INDEX(报关明细!$A$17:$V$101,ROW()-12,5) -> 0 | D19: =INDEX(报关明细!$A$17:$V$101,ROW()-12,9) -> 0 | E19: =IF(D19=0,"","PCS") | F19: =IF(G19=0,"",$F$13) | G19: =INDEX(报关明细!$A$17:$V$101,ROW()-12,13) -> 0 | H19: =IF(I19=0,"",$H$13) | I19: =INDEX(报关明细!$A$17:$V$101,ROW()-12,14) -> 0
B20: =INDEX(报关明细!$A$17:$V$101,ROW()-12,5) -> 0 | D20: =INDEX(报关明细!$A$17:$V$101,ROW()-12,9) -> 0 | E20: =IF(D20=0,"","PCS") | F20: =IF(G20=0,"",$F$13) | G20: =INDEX(报关明细!$A$17:$V$101,ROW()-12,13) -> 0 | H20: =IF(I20=0,"",$H$13) | I20: =INDEX(报关明细!$A$17:$V$101,ROW()-12,14) -> 0
B21: =INDEX(报关明细!$A$17:$V$101,ROW()-12,5) -> 0 | D21: =INDEX(报关明细!$A$17:$V$101,ROW()-12,9) -> 0 | E21: =IF(D21=0,"","PCS") | F21: =IF(G21=0,"",$F$13) | G21: =INDEX(报关明细!$A$17:$V$101,ROW()-12,13) -> 0 | H21: =IF(I21=0,"",$H$13) | I21: =INDEX(报关明细!$A$17:$V$101,ROW()-12,14) -> 0
B22: =INDEX(报关明细!$A$17:$V$101,ROW()-12,5) -> 0 | D22: =INDEX(报关明细!$A$17:$V$101,ROW()-12,9) -> 0 | E22: =IF(D22=0,"","PCS") | F22: =IF(G22=0,"",$F$13) | G22: =INDEX(报关明细!$A$17:$V$101,ROW()-12,13) -> 0 | H22: =IF(I22=0,"",$H$13) | I22: =INDEX(报关明细!$A$17:$V$101,ROW()-12,14) -> 0
B23: =INDEX(报关明细!$A$17:$V$101,ROW()-12,5) -> 0 | D23: =INDEX(报关明细!$A$17:$V$101,ROW()-12,9) -> 0 | E23: =IF(D23=0,"","PCS") | F23: =IF(G23=0,"",$F$13) | G23: =INDEX(报关明细!$A$17:$V$101,ROW()-12,13) -> 0 | H23: =IF(I23=0,"",$H$13) | I23: =INDEX(报关明细!$A$17:$V$101,ROW()-12,14) -> 0
B24: =INDEX(报关明细!$A$17:$V$101,ROW()-12,5) -> 0 | D24: =INDEX(报关明细!$A$17:$V$101,ROW()-12,9) -> 0 | E24: =IF(D24=0,"","PCS") | F24: =IF(G24=0,"",$F$13) | G24: =INDEX(报关明细!$A$17:$V$101,ROW()-12,13) -> 0 | H24: =IF(I24=0,"",$H$13) | I24: =INDEX(报关明细!$A$17:$V$101,ROW()-12,14) -> 0
B25: =INDEX(报关明细!$A$17:$V$101,ROW()-12,5) -> 0 | D25: =INDEX(报关明细!$A$17:$V$101,ROW()-12,9) -> 0 | F25: TOTAL: | H25: =报关明细!F5 -> {currency} | I25: =SUM(I13:I24) -> 0
B27: 1.More or less: with 5 % more or less both in amount & quantity allowed at the seller’s option.
B28: 2.SHIPMENT DATE: BEFROE | D28: =LEFT(报关明细!H4,10) -> {shipDate}
B29: ="3.FROM "&报关明细!D8&" TO "&报关明细!F8&" "&报关明细!B8 -> 3.FROM {departurePortName} TO {destinationPortName} {transportType}
B30: 4.Insurance: ( X )to be effected by the buyers
B31: ( ) to be effected by the seller for 100% of invoice value against
B32: F.P.A.W.ALLrisks and War Risk as per C.I.C. dated 1/1/1981
B33: 5.Terms of payment:
B34: ( X ) T/T ( ) L/C ( ) D/P
B35: 6.Shipping marks:
B36: _x000D_
B39: 7.Special clause:
B43: THE SELLERS | E43: THE BUYERS
B44: Manager( or representative) | E44: Manager(or representative)

Sheet 资料
A2: 中文名 | B2: 英文名 | C2: 英文地址 | D2: 中文地址 | E2: BANK DETAILS | F2: 海关编码 | G2: 企业编码 | H2: 姓名 | I2: 叶群飞
A3: 宁波泛太机电有限公司 | B3: NINGBO VERTAK MECHANICAL & ELECTRONIC CO.,LTD. | C3: ADD:# 288 Guangming Road Zhuangshi Zhenhai District Ningbo, China | D3: 宁波镇海庄市街道光明路288号 | E3: BANK NAME:BANK OF NINGBO ADD:NO.700 NINGNAN SOUTH ROAD,NINGBO,P.R.CHINA,315100 SWIFT :BKNBCN2N BEBEFICIATY：NINGBO VERTAK IMP AND EXP CO.,LTD ACCT.NO.：52012029000021679 ADDRESS: NO.11 GANGDONG ROAD, EAST AREA NINGBO FREE TRADE ZONE,NINGBO CHINA | F3: 3302941306 | G3: 91330211756280575H | H3: 电话 | I3: 0574-55833538
H4: 邮箱 | I4: yequnfei@vertak.com
H5: 传真 | I5: 0574-55877673
H7: 姓名 | I7: 姚磊艳
H8: 电话 | I8: 0574-55833539
H9: 邮箱 | I9: laura.yao@vertak.com
H10: 传真 | I10: 0574-55877673
H12: 姓名 | I12: 林清
H13: 电话 | I13: 0574-55833537
H14: 邮箱 | I14: linqing@vertak.com
H15: 传真 | I15: 0574-55877673
A34: CNY | B34: 人民币
A35: GBP | B35: 英镑
A36: JPY | B36: 日元
A37: EUR | B37: 欧元
A38: HKD | B38: 港币
A39: RMB | B39: 人民币
A40: USD | B40: 美元
