Workbook

Sheet 结汇单
A1: 结汇单
A2: 基本信息
A3: 发票号 | B3: {invoiceCode} | C3: 结汇单号 | D3: {code} | E3: 录入日期 | F3: {inputDate} | G3: 录入人 | H3: {inputUserName}
A4: 状态 | B4: {status} | C4: 审核日期 | E4: 审核人 | G4: 出运日期 | H4: {shipDate}
A5: 外销合同 | B5: {saleContractCode} | C5: 客户合同 | D5: {custPo} | E5: 客户编号 | F5: {custCode} | G5: 客户名称 | H5: {custName}
A6: 客户地址 | B6: {custAddress} | C6: 外销币种 | D6: {currency} | E6: 贸易国别 | F6: {tradeCountryName} | G6: 贸易方式 | H6: {tradeType}
A7: 价格条款 | B7: {settlementTermType} | C7: 结汇方式 | D7: {settlementName} | E7: 结汇方式名称 | G7: 船代公司 | H7: {forwarderCompanyName}
A8: 集装箱数量 | B8: {containerQuantity} | C8: 运输方式 | D8: {transportType} | E8: 出运口岸 | F8: {departurePortName} | G8: 目的口岸 | H8: {destinationPortName}
A9: 来源出运单号 | B9: {shipmentCode} | C9: 发票箱单 | D9: {invoicePackingList}
A10: 合计
A11: 数量合计 | B11: {totalQuantity} | C11: 箱数合计 | D11: {totalBoxes} | E11: 毛重合计 | F11: {totalGrossweight} | G11: 净重合计 | H11: {totalWeight}
A12: 体积合计 | B12: {totalVolume} | C12: 金额合计 | D12: {totalAmount}
A13: 备注信息
A14: 抬头人 | B14: {companyTitle} | C14: 备注 | D14: {remark} | E14: 收货人 | F14: {receivePerson} | G14: 通知人 | H14: {notifyPerson}
A15: 正面唛头 | B15: {frontShippingMark}
A17: 序号 | B17: 加减项 | C17: 项目 | D17: 金额
A18: {addSubItem.id} | B18: {addSubItem.calculationType} | C18: {addSubItem.feeName} | D18: {addSubItem.amountValue}
A23: 序号 | B23: 订单号 | C23: 订单序号 | D23: 物料编号 | E23: 中文品名 | F23: 英文品名 | G23: 出货数量 | H23: 单位 | I23: 销售单价 | J23: 金额 | K23: 交货日期 | L23: 客户合同 | M23: 客户货号 | N23: 海关单位 | O23: 采购币种 | P23: 采购单价 | Q23: 采购总价 | R23: 产品条码 | S23: 采购合同 | T23: 采购员编号 | U23: 采购员名称 | V23: 厂商编号 | W23: 厂商简称 | X23: 工厂货号 | Y23: 包装方式 | Z23: 特殊要求 | AA23: 内盒装量 | AB23: 外箱装量 | AC23: 箱数 | AD23: 外箱单位 | AE23: 外箱长度 | AF23: 外箱宽度 | AG23: 外箱高度 | AH23: 外箱体积 | AI23: 总体积 | AJ23: 外箱毛重 | AK23: 总毛重 | AL23: 外箱净重 | AM23: 总净重 | AN23: 中文说明 | AO23: 英文说明 | AP23: HS编码 | AQ23: 退税率% | AR23: 退税金额 | AS23: 客户编号 | AT23: 客户名称 | AU23: 业务员编号 | AV23: 业务员名称 | AW23: 收款方式编号 | AX23: 收款方式名称 | AY23: 公司/仓库发货 | AZ23: 申报要素 | BA23: 备注
A24: {childItem.sortNum} | B24: {childItem.code} | C24: {childItem.settlementFormId} | D24: {childItem.skuCode} | E24: {childItem.name} | F24: {childItem.nameEng} | G24: {childItem.shippingQuantity} | H24: {childItem.hsMeasureUnitName} | I24: {childItem.saleUnitPriceAmount} | J24: {childItem.saleAmountAmount} | K24: {childItem.deliveryDateFormat} | L24: {childItem.custPo} | M24: {childItem.cskuCode} | N24: {childItem.hsMeasureUnitName} | O24: {childItem.purchaseCurrency} | P24: {childItem.purchaseUnitPriceAmount} | Q24: {childItem.purchaseTotalAmountAmount} | R24: {childItem.sku} | S24: {childItem.purchaseContractCode} | T24: {childItem.purchaseUserCode} | U24: {childItem.purchaseUserName} | V24: {childItem.venderCode} | W24: {childItem.venderName} | X24: {childItem.venderskuCode} | Y24: {childItem.packageTypeName} | Z24: {childItem.specific} | AA24: {childItem.qtyPerInnerbox} | AB24: {childItem.qtyPerOuterbox} | AC24: {childItem.boxCount} | AD24: {childItem.unitPerOuterbox} | AE24: {childItem.outerboxLength} | AF24: {childItem.outerboxWidth} | AG24: {childItem.outerboxHeight} | AH24: {childItem.outerboxVolume} | AI24: {childItem.totalVolume} | AJ24: {childItem.outerboxGrossweightWeight} | AK24: {childItem.totalGrossweightWeight} | AL24: {childItem.outerboxNetweightWeight} | AM24: {childItem.totalNetweightWeight} | AN24: {childItem.description} | AO24: {childItem.descriptionEng} | AP24: {childItem.hsCode} | AQ24: {childItem.taxRefundRate} | AR24: {childItem.taxRefundPriceAmountAmount} | AS24: {childItem.custCode} | AT24: {childItem.custName} | AU24: {childItem.managerCode} | AV24: {childItem.managerName} | AW24: {childItem.settlementCode} | AX24: {childItem.settlementName} | AZ24: {childItem.sbys} | BA24: {childItem.remark}

Sheet 收汇箱单
B1: =结汇单!B14 -> {companyTitle}
A2: =VLOOKUP(B1,资料!A3:D9,2,0) -> #N/A
A3: =VLOOKUP(B1,资料!A1:C8,3,0) -> #N/A
B4: PACKING LIST
B5: 客 户 | C5: =结汇单!H5 -> {custName} | J5: 发票号码
B6: MESSRS | J6: INV.NO. | L6: =结汇单!B3 -> {invoiceCode}
B7: 地 址 | C7: =结汇单!B6 -> {custAddress} | J7: 日 期
B8: ADDRESS | J8: DATE: | L8: =LEFT(结汇单!F3,10) -> {inputDate
B9: 合同号码 | C9: =结汇单!D5 -> {custPo} | I9: 船 由 | J9: ="FROM "&结汇单!F8&" TO "&结汇单!H8&" "&结汇单!D8&" "&结汇单!D9 -> FROM {departurePortName} TO {destinationPortName} {transportType} {invoicePackingList}
B10: CONTRACT NO. | I10: VESSEL
B12: 订单号 | C12: 货 号 | D12: 货名 | E12: 数量 | F12: 装箱量 QTY/CTN | G12: 件数 | H12: 毛重(KGS) | J12: 净重(KGS) | L12: 体积(CBM)
B13: PO NO | C13: ITEM NO | D13: DESCRIPTION | E13: QTY (PCS） | G13: PKG （CTNS) | H13: GW/CTN | I13: T.GW | J13: NW/CTN | K13: T.NW | L13: L*W*H(CM) | M13: CBM/CTN | N13: T.CBM
B14: =结汇单!L24 -> {childItem.custPo} | C14: =结汇单!M24 -> {childItem.cskuCode} | D14: =结汇单!F24 -> {childItem.nameEng} | E14: =结汇单!G24 -> {childItem.shippingQuantity} | F14: =结汇单!AB24 -> {childItem.qtyPerOuterbox} | G14: =结汇单!AC24 -> {childItem.boxCount} | H14: =结汇单!AJ24 -> {childItem.outerboxGrossweightWeight} | I14: =结汇单!AK24 -> {childItem.totalGrossweightWeight} | J14: =结汇单!AL24 -> {childItem.outerboxNetweightWeight} | K14: =结汇单!AM24 -> {childItem.totalNetweightWeight} | L14: =IF(结汇单!AJ24=0,0,结汇单!AE24&"*"&结汇单!AF24&"*"&结汇单!AG24) -> {childItem.outerboxLength}*{childItem.outerboxWidth}*{childItem.outerboxHeight} | M14: =结汇单!AH24 -> {childItem.outerboxVolume} | N14: =结汇单!AI24 -> {childItem.totalVolume}
B15: =结汇单!L25 -> 0 | C15: =结汇单!M25 -> 0 | D15: =结汇单!F25 -> 0 | E15: =结汇单!G25 -> 0 | F15: =结汇单!AB25 -> 0 | G15: =结汇单!AC25 -> 0 | H15: =结汇单!AJ25 -> 0 | I15: =结汇单!AK25 -> 0 | J15: =结汇单!AL25 -> 0 | K15: =结汇单!AM25 -> 0 | L15: =IF(结汇单!AJ25=0,0,结汇单!AE25&"*"&结汇单!AF25&"*"&结汇单!AG25) -> 0 | M15: =结汇单!AH25 -> 0 | N15: =结汇单!AI25 -> 0
B16: =结汇单!L26 -> 0 | C16: =结汇单!M26 -> 0 | D16: =结汇单!F26 -> 0 | E16: =结汇单!G26 -> 0 | F16: =结汇单!AB26 -> 0 | G16: =结汇单!AC26 -> 0 | H16: =结汇单!AJ26 -> 0 | I16: =结汇单!AK26 -> 0 | J16: =结汇单!AL26 -> 0 | K16: =结汇单!AM26 -> 0 | L16: =IF(结汇单!AJ26=0,0,结汇单!AE26&"*"&结汇单!AF26&"*"&结汇单!AG26) -> 0 | M16: =结汇单!AH26 -> 0 | N16: =结汇单!AI26 -> 0
B17: =结汇单!L27 -> 0 | C17: =结汇单!M27 -> 0 | D17: =结汇单!F27 -> 0 | E17: =结汇单!G27 -> 0 | F17: =结汇单!AB27 -> 0 | G17: =结汇单!AC27 -> 0 | H17: =结汇单!AJ27 -> 0 | I17: =结汇单!AK27 -> 0 | J17: =结汇单!AL27 -> 0 | K17: =结汇单!AM27 -> 0 | L17: =IF(结汇单!AJ27=0,0,结汇单!AE27&"*"&结汇单!AF27&"*"&结汇单!AG27) -> 0 | M17: =结汇单!AH27 -> 0 | N17: =结汇单!AI27 -> 0
B18: =结汇单!L28 -> 0 | C18: =结汇单!M28 -> 0 | D18: =结汇单!F28 -> 0 | E18: =结汇单!G28 -> 0 | F18: =结汇单!AB28 -> 0 | G18: =结汇单!AC28 -> 0 | H18: =结汇单!AJ28 -> 0 | I18: =结汇单!AK28 -> 0 | J18: =结汇单!AL28 -> 0 | K18: =结汇单!AM28 -> 0 | L18: =IF(结汇单!AJ28=0,0,结汇单!AE28&"*"&结汇单!AF28&"*"&结汇单!AG28) -> 0 | M18: =结汇单!AH28 -> 0 | N18: =结汇单!AI28 -> 0
B19: =结汇单!L29 -> 0 | C19: =结汇单!M29 -> 0 | D19: =结汇单!F29 -> 0 | E19: =结汇单!G29 -> 0 | F19: =结汇单!AB29 -> 0 | G19: =结汇单!AC29 -> 0 | H19: =结汇单!AJ29 -> 0 | I19: =结汇单!AK29 -> 0 | J19: =结汇单!AL29 -> 0 | K19: =结汇单!AM29 -> 0 | L19: =IF(结汇单!AJ29=0,0,结汇单!AE29&"*"&结汇单!AF29&"*"&结汇单!AG29) -> 0 | M19: =结汇单!AH29 -> 0 | N19: =结汇单!AI29 -> 0
B20: =结汇单!L30 -> 0 | C20: =结汇单!M30 -> 0 | D20: =结汇单!F30 -> 0 | E20: =结汇单!G30 -> 0 | F20: =结汇单!AB30 -> 0 | G20: =结汇单!AC30 -> 0 | H20: =结汇单!AJ30 -> 0 | I20: =结汇单!AK30 -> 0 | J20: =结汇单!AL30 -> 0 | K20: =结汇单!AM30 -> 0 | L20: =IF(结汇单!AJ30=0,0,结汇单!AE30&"*"&结汇单!AF30&"*"&结汇单!AG30) -> 0 | M20: =结汇单!AH30 -> 0 | N20: =结汇单!AI30 -> 0
B21: =结汇单!L31 -> 0 | C21: =结汇单!M31 -> 0 | D21: =结汇单!F31 -> 0 | E21: =结汇单!G31 -> 0 | F21: =结汇单!AB31 -> 0 | G21: =结汇单!AC31 -> 0 | H21: =结汇单!AJ31 -> 0 | I21: =结汇单!AK31 -> 0 | J21: =结汇单!AL31 -> 0 | K21: =结汇单!AM31 -> 0 | L21: =IF(结汇单!AJ31=0,0,结汇单!AE31&"*"&结汇单!AF31&"*"&结汇单!AG31) -> 0 | M21: =结汇单!AH31 -> 0 | N21: =结汇单!AI31 -> 0
B22: =结汇单!L32 -> 0 | C22: =结汇单!M32 -> 0 | D22: =结汇单!F32 -> 0 | E22: =结汇单!G32 -> 0 | F22: =结汇单!AB32 -> 0 | G22: =结汇单!AC32 -> 0 | H22: =结汇单!AJ32 -> 0 | I22: =结汇单!AK32 -> 0 | J22: =结汇单!AL32 -> 0 | K22: =结汇单!AM32 -> 0 | L22: =IF(结汇单!AJ32=0,0,结汇单!AE32&"*"&结汇单!AF32&"*"&结汇单!AG32) -> 0 | M22: =结汇单!AH32 -> 0 | N22: =结汇单!AI32 -> 0
B23: =结汇单!L33 -> 0 | C23: =结汇单!M33 -> 0 | D23: =结汇单!F33 -> 0 | E23: =结汇单!G33 -> 0 | F23: =结汇单!AB33 -> 0 | G23: =结汇单!AC33 -> 0 | H23: =结汇单!AJ33 -> 0 | I23: =结汇单!AK33 -> 0 | J23: =结汇单!AL33 -> 0 | K23: =结汇单!AM33 -> 0 | L23: =IF(结汇单!AJ33=0,0,结汇单!AE33&"*"&结汇单!AF33&"*"&结汇单!AG33) -> 0 | M23: =结汇单!AH33 -> 0 | N23: =结汇单!AI33 -> 0
B24: =结汇单!L34 -> 0 | C24: =结汇单!M34 -> 0 | D24: =结汇单!F34 -> 0 | E24: =结汇单!G34 -> 0 | F24: =结汇单!AB34 -> 0 | G24: =结汇单!AC34 -> 0 | H24: =结汇单!AJ34 -> 0 | I24: =结汇单!AK34 -> 0 | J24: =结汇单!AL34 -> 0 | K24: =结汇单!AM34 -> 0 | L24: =IF(结汇单!AJ34=0,0,结汇单!AE34&"*"&结汇单!AF34&"*"&结汇单!AG34) -> 0 | M24: =结汇单!AH34 -> 0 | N24: =结汇单!AI34 -> 0
B25: =结汇单!L35 -> 0 | C25: =结汇单!M35 -> 0 | D25: =结汇单!F35 -> 0 | E25: =结汇单!G35 -> 0 | F25: =结汇单!AB35 -> 0 | G25: =结汇单!AC35 -> 0 | H25: =结汇单!AJ35 -> 0 | I25: =结汇单!AK35 -> 0 | J25: =结汇单!AL35 -> 0 | K25: =结汇单!AM35 -> 0 | L25: =IF(结汇单!AJ35=0,0,结汇单!AE35&"*"&结汇单!AF35&"*"&结汇单!AG35) -> 0 | M25: =结汇单!AH35 -> 0 | N25: =结汇单!AI35 -> 0
... B28: =结汇单!L38 -> 0 | C28: =结汇单!M38 -> 0 | D28: =结汇单!F38 -> 0 | E28: =结汇单!G38 -> 0 | F28: =结汇单!AB38 -> 0 | G28: =结汇单!AC38 -> 0 | H28: =结汇单!AJ38 -> 0 | I28: =结汇单!AK38 -> 0 | J28: =结汇单!AL38 -> 0 | K28: =结汇单!AM38 -> 0 | L28: =IF(结汇单!AJ38=0,0,结汇单!AE38&"*"&结汇单!AF38&"*"&结汇单!AG38) -> 0 | M28: =结汇单!AH38 -> 0 | N28: =结汇单!AI38 -> 0
B29: =结汇单!L39 -> 0 | C29: =结汇单!M39 -> 0 | D29: =结汇单!F39 -> 0 | E29: =结汇单!G39 -> 0 | F29: =结汇单!AC39 -> 0 | G29: =结汇单!AB39 -> 0 | H29: =结汇单!AJ39 -> 0 | I29: =结汇单!AK39 -> 0 | J29: =结汇单!AL39 -> 0 | K29: =结汇单!AM39 -> 0 | L29: =IF(结汇单!AJ39=0,0,结汇单!AE39&"*"&结汇单!AF39&"*"&结汇单!AG39) -> 0 | M29: =结汇单!AH39 -> 0 | N29: =结汇单!AI39 -> 0
B30: TOTAL: | E30: =结汇单!B11 -> {totalQuantity} | G30: =结汇单!D11 -> {totalBoxes} | I30: =结汇单!F11 -> {totalGrossweight} | K30: =结汇单!H11 -> {totalWeight} | N30: =结汇单!B12 -> {totalVolume}
B33: =结汇单!B15 -> {frontShippingMark}

Sheet 收汇发票
A1: =结汇单!B14 -> {companyTitle}
A2: =VLOOKUP(A1,资料!A3:D9,2,0) -> #N/A
A3: =VLOOKUP(A1,资料!A3:D9,3,0) -> #N/A
A5: COMMERCIAL INVOICE
A7: 付款方式 | B7: =结汇单!D7 -> {settlementName} | E7: 发票号码 | G7: =结汇单!B3 -> {invoiceCode}
A8: PAYMENT | E8: INV.NO.
A10: 合同号码 | B10: =结汇单!D5 -> {custPo} | E10: 日 期 | G10: =LEFT(结汇单!F3,10) -> {inputDate
A11: CONTRACT NO. | E11: DATE:
A13: 客 户 | B13: =结汇单!H5 -> {custName}
A14: MESSRS
A16: 地 址 | B16: =结汇单!B6 -> {custAddress}
A17: ADDRESS
A19: 船 由 | B19: ="FROM "&结汇单!F8&" TO "&结汇单!H8&" "&结汇单!D8 -> FROM {departurePortName} TO {destinationPortName} {transportType}
A20: VESSEL
A22: 订单号 | B22: 货 号 | C22: 货 名 | D22: 件 数 | F22: 数 量 | H22: 单 价 | J22: 金 额
A23: PO NO | B23: ITEM NO | C23: DESCRIPTION | D23: PKG | F23: QTY | H23: UNIT PRICE | J23: AMOUNT
H24: =结汇单!B7&" "&结汇单!F8 -> {settlementTermType} {departurePortName}
A25: =结汇单!L24 -> {childItem.custPo} | B25: =结汇单!M24 -> {childItem.cskuCode} | C25: =结汇单!F24 -> {childItem.nameEng} | D25: =结汇单!AC24 -> {childItem.boxCount} | E25: =结汇单!AD24 -> {childItem.unitPerOuterbox} | F25: =结汇单!G24 -> {childItem.shippingQuantity} | G25: =结汇单!H24 -> {childItem.hsMeasureUnitName} | H25: =结汇单!D6 -> {currency} | I25: =结汇单!I24 -> {childItem.saleUnitPriceAmount} | J25: =结汇单!D6 -> {currency} | K25: =结汇单!J24 -> {childItem.saleAmountAmount}
A26: =结汇单!L25 -> 0 | B26: =结汇单!M25 -> 0 | C26: =结汇单!F25 -> 0 | D26: =结汇单!AC25 -> 0 | E26: =结汇单!AD25 -> 0 | F26: =结汇单!G25 -> 0 | G26: =结汇单!H25 -> 0 | H26: =IF(I26=0,"",$H$25) | I26: =结汇单!I25 -> 0 | J26: =IF(K26=0,"",$J$25) | K26: =结汇单!J25 -> 0
A27: =结汇单!L26 -> 0 | B27: =结汇单!M26 -> 0 | C27: =结汇单!F26 -> 0 | D27: =结汇单!AC26 -> 0 | E27: =结汇单!AD26 -> 0 | F27: =结汇单!G26 -> 0 | G27: =结汇单!H26 -> 0 | H27: =IF(I27=0,"",$H$25) | I27: =结汇单!I26 -> 0 | J27: =IF(K27=0,"",$J$25) | K27: =结汇单!J26 -> 0
A28: =结汇单!L27 -> 0 | B28: =结汇单!M27 -> 0 | C28: =结汇单!F27 -> 0 | D28: =结汇单!AC27 -> 0 | E28: =结汇单!AD27 -> 0 | F28: =结汇单!G27 -> 0 | G28: =结汇单!H27 -> 0 | H28: =IF(I28=0,"",$H$25) | I28: =结汇单!I27 -> 0 | J28: =IF(K28=0,"",$J$25) | K28: =结汇单!J27 -> 0
A29: =结汇单!L28 -> 0 | B29: =结汇单!M28 -> 0 | C29: =结汇单!F28 -> 0 | D29: =结汇单!AC28 -> 0 | E29: =结汇单!AD28 -> 0 | F29: =结汇单!G28 -> 0 | G29: =结汇单!H28 -> 0 | H29: =IF(I29=0,"",$H$25) | I29: =结汇单!I28 -> 0 | J29: =IF(K29=0,"",$J$25) | K29: =结汇单!J28 -> 0
A30: =结汇单!L29 -> 0 | B30: =结汇单!M29 -> 0 | C30: =结汇单!F29 -> 0 | D30: =结汇单!AC29 -> 0 | E30: =结汇单!AD29 -> 0 | F30: =结汇单!G29 -> 0 | G30: =结汇单!H29 -> 0 | H30: =IF(I30=0,"",$H$25) | I30: =结汇单!I29 -> 0 | J30: =IF(K30=0,"",$J$25) | K30: =结汇单!J29 -> 0
A31: =结汇单!L30 -> 0 | B31: =结汇单!M30 -> 0 | C31: =结汇单!F30 -> 0 | D31: =结汇单!AC30 -> 0 | E31: =结汇单!AD30 -> 0 | F31: =结汇单!G30 -> 0 | G31: =结汇单!H30 -> 0 | H31: =IF(I31=0,"",$H$25) | I31: =结汇单!I30 -> 0 | J31: =IF(K31=0,"",$J$25) | K31: =结汇单!J30 -> 0
A32: =结汇单!L31 -> 0 | B32: =结汇单!M31 -> 0 | C32: =结汇单!F31 -> 0 | D32: =结汇单!AC31 -> 0 | E32: =结汇单!AD31 -> 0 | F32: =结汇单!G31 -> 0 | G32: =结汇单!H31 -> 0 | H32: =IF(I32=0,"",$H$25) | I32: =结汇单!I31 -> 0 | J32: =IF(K32=0,"",$J$25) | K32: =结汇单!J31 -> 0
A33: =结汇单!L32 -> 0 | B33: =结汇单!M32 -> 0 | C33: =结汇单!F32 -> 0 | D33: =结汇单!AC32 -> 0 | E33: =结汇单!AD32 -> 0 | F33: =结汇单!G32 -> 0 | G33: =结汇单!H32 -> 0 | H33: =IF(I33=0,"",$H$25) | I33: =结汇单!I32 -> 0 | J33: =IF(K33=0,"",$J$25) | K33: =结汇单!J32 -> 0
A34: =结汇单!L33 -> 0 | B34: =结汇单!M33 -> 0 | C34: =结汇单!F33 -> 0 | D34: =结汇单!AC33 -> 0 | E34: =结汇单!AD33 -> 0 | F34: =结汇单!G33 -> 0 | G34: =结汇单!H33 -> 0 | H34: =IF(I34=0,"",$H$25) | I34: =结汇单!I33 -> 0 | J34: =IF(K34=0,"",$J$25) | K34: =结汇单!J33 -> 0
A35: =结汇单!L34 -> 0 | B35: =结汇单!M34 -> 0 | C35: =结汇单!F34 -> 0 | D35: =结汇单!AC34 -> 0 | E35: =结汇单!AD34 -> 0 | F35: =结汇单!G34 -> 0 | G35: =结汇单!H34 -> 0 | H35: =IF(I35=0,"",$H$25) | I35: =结汇单!I34 -> 0 | J35: =IF(K35=0,"",$J$25) | K35: =结汇单!J34 -> 0
A36: =结汇单!L35 -> 0 | B36: =结汇单!M35 -> 0 | C36: =结汇单!F35 -> 0 | D36: =结汇单!AC35 -> 0 | E36: =结汇单!AD35 -> 0 | F36: =结汇单!G35 -> 0 | G36: =结汇单!H35 -> 0 | H36: =IF(I36=0,"",$H$25) | I36: =结汇单!I35 -> 0 | J36: =IF(K36=0,"",$J$25) | K36: =结汇单!J35 -> 0
A37: =结汇单!L36 -> 0 | B37: =结汇单!M36 -> 0 | C37: =结汇单!F36 -> 0 | D37: =结汇单!AC36 -> 0 | E37: =结汇单!AD36 -> 0 | F37: =结汇单!G36 -> 0 | G37: =结汇单!H36 -> 0 | H37: =IF(I37=0,"",$H$25) | I37: =结汇单!I36 -> 0 | J37: =IF(K37=0,"",$J$25) | K37: =结汇单!J36 -> 0
... A39: =结汇单!L38 -> 0 | B39: =结汇单!M38 -> 0 | C39: =结汇单!F38 -> 0 | D39: =结汇单!AC38 -> 0 | E39: =结汇单!AD38 -> 0 | F39: =结汇单!G38 -> 0 | G39: =结汇单!H38 -> 0 | H39: =IF(I39=0,"",$H$25) | I39: =结汇单!I38 -> 0 | J39: =IF(K39=0,"",$J$25) | K39: =结汇单!J38 -> 0
C40: =结汇单!F44 -> 0 | D40: =结汇单!AC44 -> 0 | E40: =结汇单!AD44 -> 0 | F40: =结汇单!G44 -> 0 | G40: =结汇单!H44 -> 0
C41: TOTAL: | D41: =SUM(D25:D40) -> 0 | E41: CTNS | F41: =SUM(F25:F40) -> 0 | G41: PCS | J41: =IF(K41=0,"",$H$25) | K41: =SUM(K25:K40) -> 0
A42: =结汇单!B15 -> {frontShippingMark} | H42: =IF(I42="","",$H$25) | I42: =IF(E42<>"",结汇单!D18,"")
I43: =IF(I42=0,"",SUM(I41:I42)) -> 0
A48: BANK DAETAILS：
A49: BANK NAME： | B49: =VLOOKUP(B54,银行资料!$B$2:$E$8,2,FALSE) -> BANK OF NINGBO
A50: ADD： | B50: =VLOOKUP(B54,银行资料!$B$2:$E$8,3,FALSE) -> NO.700 NINGNAN SOUTH ROAD,NINGBO,P.R.CHINA,315100
A51: SWIFT： | B51: =VLOOKUP(B54,银行资料!$B$2:$E$8,4,FALSE) -> BKNBCN2N
A52: TEL | B52: 86-574-87397598 | D52: FAX： | F52: 86-574-87397588
...

Sheet 资料
A2: 中文名 | B2: 英文名 | C2: 英文地址 | D2: 中文地址 | E2: BANK DETAILS | F2: 海关编码 | G2: 企业编码 | H2: 姓名 | I2: 叶群飞
A3: 宁波泛太机电有限公司 | B3: NINGBO VERTAK MECHANICAL & ELECTRONIC CO.,LTD. | C3: # 288 GUANGMING ROAD ZHUANGSHI ZHENHAI DISTRICT NINGBO, CHINA | D3: 宁波镇海庄市街道光明路288号 | E3: BANK NAME:BANK OF NINGBO ADD:NO.700 NINGNAN SOUTH ROAD,NINGBO,P.R.CHINA,315100 SWIFT :BKNBCN2N BEBEFICIATY：NINGBO VERTAK IMP AND EXP CO.,LTD ACCT.NO.：52012029000021679 ADDRESS: NO.11 GANGDONG ROAD, EAST AREA NINGBO FREE TRADE ZONE,NINGBO CHINA | F3: 3302941306 | G3: 91330211756280575H | I3: 电话 | J3: 0574-55833538
A4: 宁波锦林进出口有限公司 | B4: NINGBO VERTAK IMP. & EXP. CO.,LTD. | C4: NO.11 GANGDONG RD,EAST AREA,NINGBO FREE TRADE ZONE,NINGBO 315800 CHINA | F4: 3302962102 | G4: 913302017048022558 | H4: 邮箱 | I4: yequnfei@vertak.com
A5: 宁波新之戈电子商务有限公司 | B5: NINGBO SINO-GARDEN ELECTRONIC COMMERCIAL CO., LTD | F5: 3302462502 | G5: 91330201MA281Y5402 | H5: 传真 | I5: 0574-55877673
A6: NINGBO VERTAK ASSOCIATED TRADING AND INDUSTRIAL CO., LIMITED | B6: NINGBO VERTAK ASSOCIATED TRADING AND INDUSTRIAL CO., LIMITED | C6: 17/F SIU YING COMMERCIAL BUILDING 151-155 QUEENS’ ROAD CENTRA ,HK.
A7: 宁波宣哲科技有限公司 | B7: Ningbo Xuanzhe Technology Co., LTD | D7: 浙江省宁波市海曙区碶闸街58号20-34-6 | H7: 姓名 | I7: 姚磊艳
A8: 宁波知鱼电商科技有限公司 | B8: Ningbo Zhiyu E-Commerce Technology Co.,ltd | D8: 浙江省宁波市江北区长兴路689弄21号10幢112室托管3965 | H8: 电话 | I8: 0574-55833539
A9: 荃福国际照明科技有限公司 | B9: Ningbo Thrive Lighting CO.,LTD | C9: TIANYANG CROSSING THE 329 NATIONAL HIGHWAY,CIXI,NINGBO,ZHEJIANG PROVINCE | H9: 邮箱 | I9: laura.yao@vertak.com
H10: 传真 | I10: 0574-55877673
H12: 姓名 | I12: 林清
H13: 电话 | I13: 0574-55833537
H14: 邮箱 | I14: linqing@vertak.com
H15: 传真 | I15: 0574-55877673

Sheet 银行资料
A1: 银行名称 | B1: 银行账号 | C1: 银行英文名称 | D1: 银行地址 | E1: SWIFT
A2: 宁波银行 | B2: 52012029000021679 | C2: BANK OF NINGBO | D2: NO.700 NINGNAN SOUTH ROAD,NINGBO,P.R.CHINA,315100 | E2: BKNBCN2N
